Workbook

Sheet PARAMETRES
B2: PARAMÈTRES DE CONFIGURATION
B4: GUIDE LECTURE
B5: 1. SAISIE DES VENTES → Onglet VENTES (liste déroulante Enseigne)
B6: 2. TAUX AUTO → Direct=7%, Centrale=5%
B7: 3. ANALYSE → Changez le mois/année pour voir les KPIs
B8: 4. ALERTES → L'onglet SUIVI CLIENTS montre les clients à relancer
B11: 📅 SÉLECTION DE LA PÉRIODE
B13: MOIS: | C13: Août
B14: ANNÉE: | C14: 2026
B16: (numéro mois) | C16: {=MATCH(C13,{"Janvier","Février","Mars","Avril","Mai","Juin","Juillet","Août","Septembre","Octobre","Novembre","Décembre"},0)} -> 8
B18: COMMISSION
B19: TYPE | C19: TAUX
B20: Direct | C20: 0.07
B21: Centrale | C21: 0.05
B24: ⚠️ALERTES CLIENTS
B25: Mois sans commande = Alerte: | C25: 2 | D25: mois

Sheet ENSEIGNES
B1: ENSEIGNE | C1: TYPE | D1: AGENT
B2: SCAPEST | C2: Centrale | D2: BROCARD | G2: 📌 Alimenter la liste déroulante des ventes
C3: Direct | D3: CAP FRAIS
B4: SOBODIS DISTRIBUTION U EXPRESS NANTES PETIT PORT(SAS) | C4: Direct | D4: CAP FRAIS
B5: SOCAMAINE | C5: Direct | D5: CAP FRAIS
B6: LECLERC FLEURY LES AUBRIS SOCAMAINE (SAS) | C6: Direct | D6: CAP FRAIS
B7: SCACHAP | C7: Centrale | D7: CAP FRAIS
B8: U EXPRESS RENNES HOCHE ( SAS LES CONQUERANTS ) | C8: Direct | D8: CAP FRAIS
B9: LES PLATANES - ITM ROCHEFORT (SAS) | C9: Direct | D9: CAP FRAIS
C10: Direct | D10: CAP FRAIS
C11: Direct | D11: CAP FRAIS
B12: SODICHAL - HYPER U CHALLANS (SAS) | C12: Direct | D12: CAP FRAIS
B13: DISTRIBUTION - U EXPRESS NANTES PETIT PORT (SAS) | C13: Direct | D13: CAP FRAIS
B14: LECLERC FLEURY LES AUBRAIS (SOCAMAINE) | C14: Direct | D14: CAP FRAIS
C15: Direct | D15: CAP FRAIS
B16: U EXPRESS RENNES HOCHE ( SAS LES CONQUERANTS ) | C16: Direct | D16: CAP FRAIS
B17: SAS SODIHARDT (SUPER U - GUNDERSHOFFEN) | C17: Direct | D17: BROCARD
C18: Direct | D18: CAP FRAIS
B19: PARIS DISTRIBUTION (SAS) | C19: Direct | D19: CAP FRAIS
C20: Direct | D20: CAP FRAIS
B21: RENOUEST ( E.LECLERC RENNES ) (SAS) | C21: Direct | D21: CAP FRAIS
C22: Direct | D22: CAP FRAIS
B23: LES PLATANES - ITM ROCHEFORT (SAS) | C23: Direct | D23: CAP FRAIS
B24: AUCHAN HYPERMARCHE AVRILLE - SAS JUIGNEDIS (SAS) | C24: Direct | D24: CAP FRAIS
B25: PARIS DISTRIBUTION (SAS) | C25: Direct | D25: CAP FRAIS
B26: U EXPRESS RENNES HOCHE ( SAS LES CONQUERANTS ) | C26: Direct | D26: CAP FRAIS
B27: HYPER U LES HERBIERS ( SAS EXAGONE) | C27: Direct | D27: CAP FRAIS
C28: Direct | D28: CAP FRAIS
B29: LECLERC OLONNE SUR MER (SODILONNE) | C29: Direct | D29: CAP FRAIS
B30: SU NANTES CHENAIE (SAS EXPAN) CARQUEFOU | C30: Direct | D30: CAP FRAIS
B31: LECLERC SOCAMAINE SAS FONDIS | C31: Direct | D31: CAP FRAIS
B32: U EXPRESS RENNES HOCHE ( SAS LES CONQUERANTS ) | C32: Direct | D32: CAP FRAIS
C33: Direct | D33: CAP FRAIS
B34: INTERMARCHE coulounieix chamiers (COCHAME) | C34: Direct | D34: CAP FRAIS
B35: THOUARS DISTRIBUTION | C35: Direct | D35: CAP FRAIS
B36: SAS PARIS DISTRIBUTION | C36: Direct | D36: CAP FRAIS
B37: LECLERC CERNAY | C37: Direct | D37: BROCARD
B38: CARREFOUR BELGIQUE | C38: Centrale | D38: GMA GROUP
B39: SAS TRYO - ITM SAINT LAURENT DU VAR | C39: Direct | D39: SCHLESSER
B40: SAS LORIENCE ITM TOULON | C40: Direct | D40: SCHLESSER
...

Sheet VENTES
A1: 🟡 JAUNE = À REMPLIR | 🟢 VERT = CALCUL AUTO | ⚪ AUTO
A2: DATE | B2: N° BL | C2: ENSEIGNE ↓ | D2: TYPE | E2: AGENT | F2: MT HT (€) | G2: MT TTC (€) | H2: TAUX | I2: COMMISSION (€) | J2: MOIS | K2: ANNÉE | L2: NBRE D'ENSEIGNES ACTIVES DU MOIS
A3: 45964 | B3: BDL00006497 | C3: INTERMARCHE coulounieix chamiers (COCHAME) | D3: =IF(C3<>"",VLOOKUP(C3,ENSEIGNES!$B$2:$D$47,2,FALSE),"") -> Direct | E3: =IF(C3<>"",VLOOKUP(C3,ENSEIGNES!$B$2:$D$47,3,FALSE),"") -> CAP FRAIS | F3: 426.88 | G3: =F3*(1+5.5%) -> 450.3584 | H3: =IF(D3="Direct",PARAMETRES!$C$20,IF(D3="Centrale",PARAMETRES!$C$21,0)) -> 0.07 | I3: =IF(F3<>"",F3*H3,0) -> 29.8816 | J3: =IF(A3<>"",MONTH(A3),"") -> 11 | K3: =IF(A3<>"",YEAR(A3),"") -> 2025 | L3: =IF(COUNTIFS($C$3:C3,C3,$J$3:J3,J3,$K$3:K3,K3)=1,1,0) -> 1
A4: 45964 | B4: BDL00006501 | C4: THOUARS DISTRIBUTION | D4: =IF(C4<>"",VLOOKUP(C4,ENSEIGNES!$B$2:$D971,2,FALSE),"") -> Direct | E4: =IF(C4<>"",VLOOKUP(C4,ENSEIGNES!$B$2:$D971,3,FALSE),"") -> CAP FRAIS | F4: 454.72 | G4: =F4*(1+5.5%) -> 479.7296 | H4: =IF(D4="Direct",PARAMETRES!$C$20,IF(D4="Centrale",PARAMETRES!$C$21,0)) -> 0.07 | I4: =IF(F4<>"",F4*H4,0) -> 31.8304 | J4: =IF(A4<>"",MONTH(A4),"") -> 11 | K4: =IF(A4<>"",YEAR(A4),"") -> 2025 | L4: =IF(COUNTIFS($C$3:C4,C4,$J$3:J4,J4,$K$3:K4,K4)=1,1,0) -> 1
A5: 45965 | B5: BDL00006498 | C5: SCAOUEST | D5: =IF(C5<>"",VLOOKUP(C5,ENSEIGNES!$B$2:$D971,2,FALSE),"") -> Centrale | E5: =IF(C5<>"",VLOOKUP(C5,ENSEIGNES!$B$2:$D971,3,FALSE),"") -> CAP FRAIS | F5: 357.28 | G5: =F5*(1+5.5%) -> 376.9304 | H5: =IF(D5="Direct",PARAMETRES!$C$20,IF(D5="Centrale",PARAMETRES!$C$21,0)) -> 0.05 | I5: =IF(F5<>"",F5*H5,0) -> 17.864 | J5: =IF(A5<>"",MONTH(A5),"") -> 11 | K5: =IF(A5<>"",YEAR(A5),"") -> 2025 | L5: =IF(COUNTIFS($C$3:C5,C5,$J$3:J5,J5,$K$3:K5,K5)=1,1,0) -> 1
A6: 45966 | B6: BDL00006516 | C6: U EXPRESS RENNES HOCHE ( SAS LES CONQUERANTS ) | D6: =IF(C6<>"",VLOOKUP(C6,ENSEIGNES!$B$2:$D971,2,FALSE),"") -> Direct | E6: =IF(C6<>"",VLOOKUP(C6,ENSEIGNES!$B$2:$D971,3,FALSE),"") -> CAP FRAIS | F6: 361.92 | G6: =F6*(1+5.5%) -> 381.8256 | H6: =IF(D6="Direct",PARAMETRES!$C$20,IF(D6="Centrale",PARAMETRES!$C$21,0)) -> 0.07 | I6: =IF(F6<>"",F6*H6,0) -> 25.3344 | J6: =IF(A6<>"",MONTH(A6),"") -> 11 | K6: =IF(A6<>"",YEAR(A6),"") -> 2025 | L6: =IF(COUNTIFS($C$3:C6,C6,$J$3:J6,J6,$K$3:K6,K6)=1,1,0) -> 1
A7: 45967 | B7: BDL00006517 | C7: RENOUEST ( E.LECLERC RENNES ) (SAS) | D7: =IF(C7<>"",VLOOKUP(C7,ENSEIGNES!$B$2:$D971,2,FALSE),"") -> Direct | E7: =IF(C7<>"",VLOOKUP(C7,ENSEIGNES!$B$2:$D971,3,FALSE),"") -> CAP FRAIS | F7: 418.14 | G7: =F7*(1+5.5%) -> 441.1377 | H7: =IF(D7="Direct",PARAMETRES!$C$20,IF(D7="Centrale",PARAMETRES!$C$21,0)) -> 0.07 | I7: =IF(F7<>"",F7*H7,0) -> 29.2698 | J7: =IF(A7<>"",MONTH(A7),"") -> 11 | K7: =IF(A7<>"",YEAR(A7),"") -> 2025 | L7: =IF(COUNTIFS($C$3:C7,C7,$J$3:J7,J7,$K$3:K7,K7)=1,1,0) -> 1
A8: 45973 | B8: BDL00006547 | C8: LECLERC SOCAMAINE SAS FONDIS | D8: =IF(C8<>"",VLOOKUP(C8,ENSEIGNES!$B$2:$D971,2,FALSE),"") -> Direct | E8: =IF(C8<>"",VLOOKUP(C8,ENSEIGNES!$B$2:$D971,3,FALSE),"") -> CAP FRAIS | F8: 464 | G8: =F8*(1+5.5%) -> 489.52 | H8: =IF(D8="Direct",PARAMETRES!$C$20,IF(D8="Centrale",PARAMETRES!$C$21,0)) -> 0.07 | I8: =IF(F8<>"",F8*H8,0) -> 32.48 | J8: =IF(A8<>"",MONTH(A8),"") -> 11 | K8: =IF(A8<>"",YEAR(A8),"") -> 2025 | L8: =IF(COUNTIFS($C$3:C8,C8,$J$3:J8,J8,$K$3:K8,K8)=1,1,0) -> 1
A9: 45973 | B9: BDL00006546 | C9: SU NANTES CHENAIE (SAS EXPAN) CARQUEFOU | D9: =IF(C9<>"",VLOOKUP(C9,ENSEIGNES!$B$2:$D971,2,FALSE),"") -> Direct | E9: =IF(C9<>"",VLOOKUP(C9,ENSEIGNES!$B$2:$D971,3,FALSE),"") -> CAP FRAIS | F9: 361.92 | G9: =F9*(1+5.5%) -> 381.8256 | H9: =IF(D9="Direct",PARAMETRES!$C$20,IF(D9="Centrale",PARAMETRES!$C$21,0)) -> 0.07 | I9: =IF(F9<>"",F9*H9,0) -> 25.3344 | J9: =IF(A9<>"",MONTH(A9),"") -> 11 | K9: =IF(A9<>"",YEAR(A9),"") -> 2025 | L9: =IF(COUNTIFS($C$3:C9,C9,$J$3:J9,J9,$K$3:K9,K9)=1,1,0) -> 1
A10: 45975 | B10: BDL00006585 | C10: LECLERC OLONNE SUR MER (SODILONNE) | D10: =IF(C10<>"",VLOOKUP(C10,ENSEIGNES!$B$2:$D971,2,FALSE),"") -> Direct | E10: =IF(C10<>"",VLOOKUP(C10,ENSEIGNES!$B$2:$D971,3,FALSE),"") -> CAP FRAIS | F10: 487.2 | G10: =F10*(1+5.5%) -> 513.996 | H10: =IF(D10="Direct",PARAMETRES!$C$20,IF(D10="Centrale",PARAMETRES!$C$21,0)) -> 0.07 | I10: =IF(F10<>"",F10*H10,0) -> 34.104 | J10: =IF(A10<>"",MONTH(A10),"") -> 11 | K10: =IF(A10<>"",YEAR(A10),"") -> 2025 | L10: =IF(COUNTIFS($C$3:C10,C10,$J$3:J10,J10,$K$3:K10,K10)=1,1,0) -> 1
A11: 45975 | B11: BDL00006584 | C11: SCAOUEST | D11: =IF(C11<>"",VLOOKUP(C11,ENSEIGNES!$B$2:$D971,2,FALSE),"") -> Centrale | E11: =IF(C11<>"",VLOOKUP(C11,ENSEIGNES!$B$2:$D971,3,FALSE),"") -> CAP FRAIS | F11: 556.8 | G11: =F11*(1+5.5%) -> 587.424 | H11: =IF(D11="Direct",PARAMETRES!$C$20,IF(D11="Centrale",PARAMETRES!$C$21,0)) -> 0.05 | I11: =IF(F11<>"",F11*H11,0) -> 27.84 | J11: =IF(A11<>"",MONTH(A11),"") -> 11 | K11: =IF(A11<>"",YEAR(A11),"") -> 2025 | L11: =IF(COUNTIFS($C$3:C11,C11,$J$3:J11,J11,$K$3:K11,K11)=1,1,0) -> 0
A12: 45975 | B12: BDL00006581 | C12: HYPER U LES HERBIERS ( SAS EXAGONE) | D12: =IF(C12<>"",VLOOKUP(C12,ENSEIGNES!$B$2:$D971,2,FALSE),"") -> Direct | E12: =IF(C12<>"",VLOOKUP(C12,ENSEIGNES!$B$2:$D971,3,FALSE),"") -> CAP FRAIS | F12: 709.92 | G12: =F12*(1+5.5%) -> 748.9656 | H12: =IF(D12="Direct",PARAMETRES!$C$20,IF(D12="Centrale",PARAMETRES!$C$21,0)) -> 0.07 | I12: =IF(F12<>"",F12*H12,0) -> 49.6944 | J12: =IF(A12<>"",MONTH(A12),"") -> 11 | K12: =IF(A12<>"",YEAR(A12),"") -> 2025 | L12: =IF(COUNTIFS($C$3:C12,C12,$J$3:J12,J12,$K$3:K12,K12)=1,1,0) -> 1
A13: 45975 | B13: BDL00006569 | C13: SAS PARIS DISTRIBUTION | D13: =IF(C13<>"",VLOOKUP(C13,ENSEIGNES!$B$2:$D971,2,FALSE),"") -> Direct | E13: =IF(C13<>"",VLOOKUP(C13,ENSEIGNES!$B$2:$D971,3,FALSE),"") -> CAP FRAIS | F13: 719.2 | G13: =F13*(1+5.5%) -> 758.756 | H13: =IF(D13="Direct",PARAMETRES!$C$20,IF(D13="Centrale",PARAMETRES!$C$21,0)) -> 0.07 | I13: =IF(F13<>"",F13*H13,0) -> 50.344 | J13: =IF(A13<>"",MONTH(A13),"") -> 11 | K13: =IF(A13<>"",YEAR(A13),"") -> 2025 | L13: =IF(COUNTIFS($C$3:C13,C13,$J$3:J13,J13,$K$3:K13,K13)=1,1,0) -> 1
A14: 45975 | B14: BDL00006580 | C14: U EXPRESS RENNES HOCHE ( SAS LES CONQUERANTS ) | D14: =IF(C14<>"",VLOOKUP(C14,ENSEIGNES!$B$2:$D971,2,FALSE),"") -> Direct | E14: =IF(C14<>"",VLOOKUP(C14,ENSEIGNES!$B$2:$D971,3,FALSE),"") -> CAP FRAIS | F14: 454.72 | G14: =F14*(1+5.5%) -> 479.7296 | H14: =IF(D14="Direct",PARAMETRES!$C$20,IF(D14="Centrale",PARAMETRES!$C$21,0)) -> 0.07 | I14: =IF(F14<>"",F14*H14,0) -> 31.8304 | J14: =IF(A14<>"",MONTH(A14),"") -> 11 | K14: =IF(A14<>"",YEAR(A14),"") -> 2025 | L14: =IF(COUNTIFS($C$3:C14,C14,$J$3:J14,J14,$K$3:K14,K14)=1,1,0) -> 0
A15: 45979 | B15: BDL00006591 | C15: SCAOUEST | D15: =IF(C15<>"",VLOOKUP(C15,ENSEIGNES!$B$2:$D971,2,FALSE),"") -> Centrale | E15: =IF(C15<>"",VLOOKUP(C15,ENSEIGNES!$B$2:$D971,3,FALSE),"") -> CAP FRAIS | F15: 431.52 | G15: =F15*(1+5.5%) -> 455.2536 | H15: =IF(D15="Direct",PARAMETRES!$C$20,IF(D15="Centrale",PARAMETRES!$C$21,0)) -> 0.05 | I15: =IF(F15<>"",F15*H15,0) -> 21.576 | J15: =IF(A15<>"",MONTH(A15),"") -> 11 | K15: =IF(A15<>"",YEAR(A15),"") -> 2025 | L15: =IF(COUNTIFS($C$3:C15,C15,$J$3:J15,J15,$K$3:K15,K15)=1,1,0) -> 0
A16: 45981 | B16: BDL00006616 | C16: AUCHAN HYPERMARCHE AVRILLE - SAS JUIGNEDIS (SAS) | D16: =IF(C16<>"",VLOOKUP(C16,ENSEIGNES!$B$2:$D971,2,FALSE),"") -> Direct | E16: =IF(C16<>"",VLOOKUP(C16,ENSEIGNES!$B$2:$D971,3,FALSE),"") -> CAP FRAIS | F16: 412.96 | G16: =F16*(1+5.5%) -> 435.6728 | H16: =IF(D16="Direct",PARAMETRES!$C$20,IF(D16="Centrale",PARAMETRES!$C$21,0)) -> 0.07 | I16: =IF(F16<>"",F16*H16,0) -> 28.9072 | J16: =IF(A16<>"",MONTH(A16),"") -> 11 | K16: =IF(A16<>"",YEAR(A16),"") -> 2025 | L16: =IF(COUNTIFS($C$3:C16,C16,$J$3:J16,J16,$K$3:K16,K16)=1,1,0) -> 1
A17: 45981 | B17: BDL00006615 | C17: LES PLATANES - ITM ROCHEFORT (SAS) | D17: =IF(C17<>"",VLOOKUP(C17,ENSEIGNES!$B$2:$D971,2,FALSE),"") -> Direct | E17: =IF(C17<>"",VLOOKUP(C17,ENSEIGNES!$B$2:$D971,3,FALSE),"") -> CAP FRAIS | F17: 375.84 | G17: =F17*(1+5.5%) -> 396.5112 | H17: =IF(D17="Direct",PARAMETRES!$C$20,IF(D17="Centrale",PARAMETRES!$C$21,0)) -> 0.07 | I17: =IF(F17<>"",F17*H17,0) -> 26.3088 | J17: =IF(A17<>"",MONTH(A17),"") -> 11 | K17: =IF(A17<>"",YEAR(A17),"") -> 2025 | L17: =IF(COUNTIFS($C$3:C17,C17,$J$3:J17,J17,$K$3:K17,K17)=1,1,0) -> 1
A18: 45987 | B18: BDL00006651 | C18: SCAOUEST | D18: =IF(C18<>"",VLOOKUP(C18,ENSEIGNES!$B$2:$D971,2,FALSE),"") -> Centrale | E18: =IF(C18<>"",VLOOKUP(C18,ENSEIGNES!$B$2:$D971,3,FALSE),"") -> CAP FRAIS | F18: 357.28 | G18: =F18*(1+5.5%) -> 376.9304 | H18: =IF(D18="Direct",PARAMETRES!$C$20,IF(D18="Centrale",PARAMETRES!$C$21,0)) -> 0.05 | I18: =IF(F18<>"",F18*H18,0) -> 17.864 | J18: =IF(A18<>"",MONTH(A18),"") -> 11 | K18: =IF(A18<>"",YEAR(A18),"") -> 2025 | L18: =IF(COUNTIFS($C$3:C18,C18,$J$3:J18,J18,$K$3:K18,K18)=1,1,0) -> 0
A19: 45987 | B19: BDL00006650 | C19: RENOUEST ( E.LECLERC RENNES ) (SAS) | D19: =IF(C19<>"",VLOOKUP(C19,ENSEIGNES!$B$2:$D971,2,FALSE),"") -> Direct | E19: =IF(C19<>"",VLOOKUP(C19,ENSEIGNES!$B$2:$D971,3,FALSE),"") -> CAP FRAIS | F19: 418.14 | G19: =F19*(1+5.5%) -> 441.1377 | H19: =IF(D19="Direct",PARAMETRES!$C$20,IF(D19="Centrale",PARAMETRES!$C$21,0)) -> 0.07 | I19: =IF(F19<>"",F19*H19,0) -> 29.2698 | J19: =IF(A19<>"",MONTH(A19),"") -> 11 | K19: =IF(A19<>"",YEAR(A19),"") -> 2025 | L19: =IF(COUNTIFS($C$3:C19,C19,$J$3:J19,J19,$K$3:K19,K19)=1,1,0) -> 0
A20: 45989 | B20: BDL00006673 | C20: SCAOUEST | D20: =IF(C20<>"",VLOOKUP(C20,ENSEIGNES!$B$2:$D971,2,FALSE),"") -> Centrale | E20: =IF(C20<>"",VLOOKUP(C20,ENSEIGNES!$B$2:$D971,3,FALSE),"") -> CAP FRAIS | F20: 728.48 | G20: =F20*(1+5.5%) -> 768.5464 | H20: =IF(D20="Direct",PARAMETRES!$C$20,IF(D20="Centrale",PARAMETRES!$C$21,0)) -> 0.05 | I20: =IF(F20<>"",F20*H20,0) -> 36.424 | J20: =IF(A20<>"",MONTH(A20),"") -> 11 | K20: =IF(A20<>"",YEAR(A20),"") -> 2025 | L20: =IF(COUNTIFS($C$3:C20,C20,$J$3:J20,J20,$K$3:K20,K20)=1,1,0) -> 0
A21: 45993 | B21: BDL00006675 | C21: SCAOUEST | D21: =IF(C21<>"",VLOOKUP(C21,ENSEIGNES!$B$2:$D971,2,FALSE),"") -> Centrale | E21: =IF(C21<>"",VLOOKUP(C21,ENSEIGNES!$B$2:$D971,3,FALSE),"") -> CAP FRAIS | F21: 464 | G21: =F21*(1+5.5%) -> 489.52 | H21: =IF(D21="Direct",PARAMETRES!$C$20,IF(D21="Centrale",PARAMETRES!$C$21,0)) -> 0.05 | I21: =IF(F21<>"",F21*H21,0) -> 23.2 | J21: =IF(A21<>"",MONTH(A21),"") -> 12 | K21: =IF(A21<>"",YEAR(A21),"") -> 2025 | L21: =IF(COUNTIFS($C$3:C21,C21,$J$3:J21,J21,$K$3:K21,K21)=1,1,0) -> 1
A22: 45994 | B22: BDL00006696 | C22: SAS PARIS DISTRIBUTION | D22: =IF(C22<>"",VLOOKUP(C22,ENSEIGNES!$B$2:$D971,2,FALSE),"") -> Direct | E22: =IF(C22<>"",VLOOKUP(C22,ENSEIGNES!$B$2:$D971,3,FALSE),"") -> CAP FRAIS | F22: 812 | G22: =F22*(1+5.5%) -> 856.66 | H22: =IF(D22="Direct",PARAMETRES!$C$20,IF(D22="Centrale",PARAMETRES!$C$21,0)) -> 0.07 | I22: =IF(F22<>"",F22*H22,0) -> 56.84 | J22: =IF(A22<>"",MONTH(A22),"") -> 12 | K22: =IF(A22<>"",YEAR(A22),"") -> 2025 | L22: =IF(COUNTIFS($C$3:C22,C22,$J$3:J22,J22,$K$3:K22,K22)=1,1,0) -> 1
A23: 45995 | B23: BDL00006703 | C23: SCAOUEST | D23: =IF(C23<>"",VLOOKUP(C23,ENSEIGNES!$B$2:$D971,2,FALSE),"") -> Centrale | E23: =IF(C23<>"",VLOOKUP(C23,ENSEIGNES!$B$2:$D971,3,FALSE),"") -> CAP FRAIS | F23: 464 | G23: =F23*(1+5.5%) -> 489.52 | H23: =IF(D23="Direct",PARAMETRES!$C$20,IF(D23="Centrale",PARAMETRES!$C$21,0)) -> 0.05 | I23: =IF(F23<>"",F23*H23,0) -> 23.2 | J23: =IF(A23<>"",MONTH(A23),"") -> 12 | K23: =IF(A23<>"",YEAR(A23),"") -> 2025 | L23: =IF(COUNTIFS($C$3:C23,C23,$J$3:J23,J23,$K$3:K23,K23)=1,1,0) -> 0
A24: 46010 | B24: BDL00006792 | C24: SCAOUEST | D24: =IF(C24<>"",VLOOKUP(C24,ENSEIGNES!$B$2:$D971,2,FALSE),"") -> Centrale | E24: =IF(C24<>"",VLOOKUP(C24,ENSEIGNES!$B$2:$D971,3,FALSE),"") -> CAP FRAIS | F24: 635.68 | G24: =F24*(1+5.5%) -> 670.6424 | H24: =IF(D24="Direct",PARAMETRES!$C$20,IF(D24="Centrale",PARAMETRES!$C$21,0)) -> 0.05 | I24: =IF(F24<>"",F24*H24,0) -> 31.784 | J24: =IF(A24<>"",MONTH(A24),"") -> 12 | K24: =IF(A24<>"",YEAR(A24),"") -> 2025 | L24: =IF(COUNTIFS($C$3:C24,C24,$J$3:J24,J24,$K$3:K24,K24)=1,1,0) -> 0
A25: 46022 | B25: BDL00006852 | C25: U EXPRESS RENNES HOCHE ( SAS LES CONQUERANTS ) | D25: =IF(C25<>"",VLOOKUP(C25,ENSEIGNES!$B$2:$D971,2,FALSE),"") -> Direct | E25: =IF(C25<>"",VLOOKUP(C25,ENSEIGNES!$B$2:$D971,3,FALSE),"") -> CAP FRAIS | F25: 459.36 | G25: =F25*(1+5.5%) -> 484.6248 | H25: =IF(D25="Direct",PARAMETRES!$C$20,IF(D25="Centrale",PARAMETRES!$C$21,0)) -> 0.07 | I25: =IF(F25<>"",F25*H25,0) -> 32.1552 | J25: =IF(A25<>"",MONTH(A25),"") -> 12 | K25: =IF(A25<>"",YEAR(A25),"") -> 2025 | L25: =IF(COUNTIFS($C$3:C25,C25,$J$3:J25,J25,$K$3:K25,K25)=1,1,0) -> 1
A26: 46034 | B26: BDL00006917 | C26: LECLERC FLEURY LES AUBRAIS (SOCAMAINE) | D26: =IF(C26<>"",VLOOKUP(C26,ENSEIGNES!$B$2:$D971,2,FALSE),"") -> Direct | E26: =IF(C26<>"",VLOOKUP(C26,ENSEIGNES!$B$2:$D971,3,FALSE),"") -> CAP FRAIS | F26: 457.12 | G26: =F26*(1+5.5%) -> 482.2616 | H26: =IF(D26="Direct",PARAMETRES!$C$20,IF(D26="Centrale",PARAMETRES!$C$21,0)) -> 0.07 | I26: =IF(F26<>"",F26*H26,0) -> 31.9984 | J26: =IF(A26<>"",MONTH(A26),"") -> 1 | K26: =IF(A26<>"",YEAR(A26),"") -> 2026 | L26: =IF(COUNTIFS($C$3:C26,C26,$J$3:J26,J26,$K$3:K26,K26)=1,1,0) -> 1
A27: 46034 | B27: BDL00006918 | C27: SCAOUEST | D27: =IF(C27<>"",VLOOKUP(C27,ENSEIGNES!$B$2:$D971,2,FALSE),"") -> Centrale | E27: =IF(C27<>"",VLOOKUP(C27,ENSEIGNES!$B$2:$D971,3,FALSE),"") -> CAP FRAIS | F27: 431.52 | G27: =F27*(1+5.5%) -> 455.2536 | H27: =IF(D27="Direct",PARAMETRES!$C$20,IF(D27="Centrale",PARAMETRES!$C$21,0)) -> 0.05 | I27: =IF(F27<>"",F27*H27,0) -> 21.576 | J27: =IF(A27<>"",MONTH(A27),"") -> 1 | K27: =IF(A27<>"",YEAR(A27),"") -> 2026 | L27: =IF(COUNTIFS($C$3:C27,C27,$J$3:J27,J27,$K$3:K27,K27)=1,1,0) -> 1
A28: 46037 | B28: BDL00006946 | C28: SODICHAL - HYPER U CHALLANS (SAS) | D28: =IF(C28<>"",VLOOKUP(C28,ENSEIGNES!$B$2:$D971,2,FALSE),"") -> Direct | E28: =IF(C28<>"",VLOOKUP(C28,ENSEIGNES!$B$2:$D971,3,FALSE),"") -> CAP FRAIS | F28: 450.08 | G28: =F28*(1+5.5%) -> 474.8344 | H28: =IF(D28="Direct",PARAMETRES!$C$20,IF(D28="Centrale",PARAMETRES!$C$21,0)) -> 0.07 | I28: =IF(F28<>"",F28*H28,0) -> 31.5056 | J28: =IF(A28<>"",MONTH(A28),"") -> 1 | K28: =IF(A28<>"",YEAR(A28),"") -> 2026 | L28: =IF(COUNTIFS($C$3:C28,C28,$J$3:J28,J28,$K$3:K28,K28)=1,1,0) -> 1
A29: 46037 | B29: BDL00006947 | C29: SOBODIS DISTRIBUTION U EXPRESS NANTES PETIT PORT(SAS) | D29: =IF(C29<>"",VLOOKUP(C29,ENSEIGNES!$B$2:$D971,2,FALSE),"") -> Direct | E29: =IF(C29<>"",VLOOKUP(C29,ENSEIGNES!$B$2:$D971,3,FALSE),"") -> CAP FRAIS | F29: 366.56 | G29: =F29*(1+5.5%) -> 386.7208 | H29: =IF(D29="Direct",PARAMETRES!$C$20,IF(D29="Centrale",PARAMETRES!$C$21,0)) -> 0.07 | I29: =IF(F29<>"",F29*H29,0) -> 25.6592 | J29: =IF(A29<>"",MONTH(A29),"") -> 1 | K29: =IF(A29<>"",YEAR(A29),"") -> 2026 | L29: =IF(COUNTIFS($C$3:C29,C29,$J$3:J29,J29,$K$3:K29,K29)=1,1,0) -> 1
A30: 46039 | B30: BDL00006959 | C30: SCAOUEST | D30: =IF(C30<>"",VLOOKUP(C30,ENSEIGNES!$B$2:$D971,2,FALSE),"") -> Centrale | E30: =IF(C30<>"",VLOOKUP(C30,ENSEIGNES!$B$2:$D971,3,FALSE),"") -> CAP FRAIS | F30: 812 | G30: =F30*(1+5.5%) -> 856.66 | H30: =IF(D30="Direct",PARAMETRES!$C$20,IF(D30="Centrale",PARAMETRES!$C$21,0)) -> 0.05 | I30: =IF(F30<>"",F30*H30,0) -> 40.6 | J30: =IF(A30<>"",MONTH(A30),"") -> 1 | K30: =IF(A30<>"",YEAR(A30),"") -> 2026 | L30: =IF(COUNTIFS($C$3:C30,C30,$J$3:J30,J30,$K$3:K30,K30)=1,1,0) -> 0
A31: 46039 | B31: BDL00006962 | C31: OTERA SAS | D31: =IF(C31<>"",VLOOKUP(C31,ENSEIGNES!$B$2:$D971,2,FALSE),"") -> Centrale | E31: =IF(C31<>"",VLOOKUP(C31,ENSEIGNES!$B$2:$D971,3,FALSE),"") -> CAP FRAIS | F31: 361.92 | G31: =F31*(1+5.5%) -> 381.8256 | H31: =IF(D31="Direct",PARAMETRES!$C$20,IF(D31="Centrale",PARAMETRES!$C$21,0)) -> 0.05 | I31: =IF(F31<>"",F31*H31,0) -> 18.096 | J31: =IF(A31<>"",MONTH(A31),"") -> 1 | K31: =IF(A31<>"",YEAR(A31),"") -> 2026 | L31: =IF(COUNTIFS($C$3:C31,C31,$J$3:J31,J31,$K$3:K31,K31)=1,1,0) -> 1
A32: 46042 | B32: BDL00006960 | C32: SCAOUEST | D32: =IF(C32<>"",VLOOKUP(C32,ENSEIGNES!$B$2:$D971,2,FALSE),"") -> Centrale | E32: =IF(C32<>"",VLOOKUP(C32,ENSEIGNES!$B$2:$D971,3,FALSE),"") -> CAP FRAIS | F32: 491.84 | G32: =F32*(1+5.5%) -> 518.8912 | H32: =IF(D32="Direct",PARAMETRES!$C$20,IF(D32="Centrale",PARAMETRES!$C$21,0)) -> 0.05 | I32: =IF(F32<>"",F32*H32,0) -> 24.592 | J32: =IF(A32<>"",MONTH(A32),"") -> 1 | K32: =IF(A32<>"",YEAR(A32),"") -> 2026 | L32: =IF(COUNTIFS($C$3:C32,C32,$J$3:J32,J32,$K$3:K32,K32)=1,1,0) -> 0
A33: 46043 | B33: BDL00006989 | C33: LES PLATANES - ITM ROCHEFORT (SAS) | D33: =IF(C33<>"",VLOOKUP(C33,ENSEIGNES!$B$2:$D971,2,FALSE),"") -> Direct | E33: =IF(C33<>"",VLOOKUP(C33,ENSEIGNES!$B$2:$D971,3,FALSE),"") -> CAP FRAIS | F33: 417.6 | G33: =F33*(1+5.5%) -> 440.568 | H33: =IF(D33="Direct",PARAMETRES!$C$20,IF(D33="Centrale",PARAMETRES!$C$21,0)) -> 0.07 | I33: =IF(F33<>"",F33*H33,0) -> 29.232 | J33: =IF(A33<>"",MONTH(A33),"") -> 1 | K33: =IF(A33<>"",YEAR(A33),"") -> 2026 | L33: =IF(COUNTIFS($C$3:C33,C33,$J$3:J33,J33,$K$3:K33,K33)=1,1,0) -> 1
A34: 46045 | B34: BDL00006996 | C34: SODICHAL - HYPER U CHALLANS (SAS) | D34: =IF(C34<>"",VLOOKUP(C34,ENSEIGNES!$B$2:$D971,2,FALSE),"") -> Direct | E34: =IF(C34<>"",VLOOKUP(C34,ENSEIGNES!$B$2:$D971,3,FALSE),"") -> CAP FRAIS | F34: 547.52 | G34: =F34*(1+5.5%) -> 577.6336 | H34: =IF(D34="Direct",PARAMETRES!$C$20,IF(D34="Centrale",PARAMETRES!$C$21,0)) -> 0.07 | I34: =IF(F34<>"",F34*H34,0) -> 38.3264 | J34: =IF(A34<>"",MONTH(A34),"") -> 1 | K34: =IF(A34<>"",YEAR(A34),"") -> 2026 | L34: =IF(COUNTIFS($C$3:C34,C34,$J$3:J34,J34,$K$3:K34,K34)=1,1,0) -> 0
A35: 46045 | B35: BDL00006995 | C35: U EXPRESS RENNES HOCHE ( SAS LES CONQUERANTS ) | D35: =IF(C35<>"",VLOOKUP(C35,ENSEIGNES!$B$2:$D971,2,FALSE),"") -> Direct | E35: =IF(C35<>"",VLOOKUP(C35,ENSEIGNES!$B$2:$D971,3,FALSE),"") -> CAP FRAIS | F35: 139.2 | G35: =F35*(1+5.5%) -> 146.856 | H35: =IF(D35="Direct",PARAMETRES!$C$20,IF(D35="Centrale",PARAMETRES!$C$21,0)) -> 0.07 | I35: =IF(F35<>"",F35*H35,0) -> 9.744 | J35: =IF(A35<>"",MONTH(A35),"") -> 1 | K35: =IF(A35<>"",YEAR(A35),"") -> 2026 | L35: =IF(COUNTIFS($C$3:C35,C35,$J$3:J35,J35,$K$3:K35,K35)=1,1,0) -> 1
A36: 46049 | B36: BDL00007027 | C36: SCAOUEST | D36: =IF(C36<>"",VLOOKUP(C36,ENSEIGNES!$B$2:$D971,2,FALSE),"") -> Centrale | E36: =IF(C36<>"",VLOOKUP(C36,ENSEIGNES!$B$2:$D971,3,FALSE),"") -> CAP FRAIS | F36: 450.08 | G36: =F36*(1+5.5%) -> 474.8344 | H36: =IF(D36="Direct",PARAMETRES!$C$20,IF(D36="Centrale",PARAMETRES!$C$21,0)) -> 0.05 | I36: =IF(F36<>"",F36*H36,0) -> 22.504 | J36: =IF(A36<>"",MONTH(A36),"") -> 1 | K36: =IF(A36<>"",YEAR(A36),"") -> 2026 | L36: =IF(COUNTIFS($C$3:C36,C36,$J$3:J36,J36,$K$3:K36,K36)=1,1,0) -> 0
A37: 46050 | B37: BDL00007045 | C37: SODICHAL - HYPER U CHALLANS (SAS) | D37: =IF(C37<>"",VLOOKUP(C37,ENSEIGNES!$B$2:$D971,2,FALSE),"") -> Direct | E37: =IF(C37<>"",VLOOKUP(C37,ENSEIGNES!$B$2:$D971,3,FALSE),"") -> CAP FRAIS | F37: 1127.52 | G37: =F37*(1+5.5%) -> 1189.5336 | H37: =IF(D37="Direct",PARAMETRES!$C$20,IF(D37="Centrale",PARAMETRES!$C$21,0)) -> 0.07 | I37: =IF(F37<>"",F37*H37,0) -> 78.9264 | J37: =IF(A37<>"",MONTH(A37),"") -> 1 | K37: =IF(A37<>"",YEAR(A37),"") -> 2026 | L37: =IF(COUNTIFS($C$3:C37,C37,$J$3:J37,J37,$K$3:K37,K37)=1,1,0) -> 0
A38: 46050 | B38: BDL00007046 | C38: SCAOUEST | D38: =IF(C38<>"",VLOOKUP(C38,ENSEIGNES!$B$2:$D971,2,FALSE),"") -> Centrale | E38: =IF(C38<>"",VLOOKUP(C38,ENSEIGNES!$B$2:$D971,3,FALSE),"") -> CAP FRAIS | F38: 830.56 | G38: =F38*(1+5.5%) -> 876.2408 | H38: =IF(D38="Direct",PARAMETRES!$C$20,IF(D38="Centrale",PARAMETRES!$C$21,0)) -> 0.05 | I38: =IF(F38<>"",F38*H38,0) -> 41.528 | J38: =IF(A38<>"",MONTH(A38),"") -> 1 | K38: =IF(A38<>"",YEAR(A38),"") -> 2026 | L38: =IF(COUNTIFS($C$3:C38,C38,$J$3:J38,J38,$K$3:K38,K38)=1,1,0) -> 0
A39: 46052 | B39: BDL00007078 | C39: OTERA SAS | D39: =IF(C39<>"",VLOOKUP(C39,ENSEIGNES!$B$2:$D971,2,FALSE),"") -> Centrale | E39: =IF(C39<>"",VLOOKUP(C39,ENSEIGNES!$B$2:$D971,3,FALSE),"") -> CAP FRAIS | F39: 394.4 | G39: =F39*(1+5.5%) -> 416.092 | H39: =IF(D39="Direct",PARAMETRES!$C$20,IF(D39="Centrale",PARAMETRES!$C$21,0)) -> 0.05 | I39: =IF(F39<>"",F39*H39,0) -> 19.72 | J39: =IF(A39<>"",MONTH(A39),"") -> 1 | K39: =IF(A39<>"",YEAR(A39),"") -> 2026 | L39: =IF(COUNTIFS($C$3:C39,C39,$J$3:J39,J39,$K$3:K39,K39)=1,1,0) -> 0
A40: 46043 | B40: BDL00006992 | C40: HYPER U LES HERBIERS ( SAS EXAGONE) | D40: =IF(C40<>"",VLOOKUP(C40,ENSEIGNES!$B$2:$D971,2,FALSE),"") -> Direct | E40: =IF(C40<>"",VLOOKUP(C40,ENSEIGNES!$B$2:$D971,3,FALSE),"") -> CAP FRAIS | F40: 477.92 | G40: =F40*(1+5.5%) -> 504.2056 | H40: =IF(D40="Direct",PARAMETRES!$C$20,IF(D40="Centrale",PARAMETRES!$C$21,0)) -> 0.07 | I40: =IF(F40<>"",F40*H40,0) -> 33.4544 | J40: =IF(A40<>"",MONTH(A40),"") -> 1 | K40: =IF(A40<>"",YEAR(A40),"") -> 2026 | L40: =IF(COUNTIFS($C$3:C40,C40,$J$3:J40,J40,$K$3:K40,K40)=1,1,0) -> 1
...

Sheet SUIVI MENSUEL COMPLET
A1: SUIVI MENSUEL COMPLET
A2: 📅 Période: | B2: =PARAMETRES!C13 -> Août | C2: =PARAMETRES!C14 -> 2026
A4: 1. RÉSUMÉ GLOBAL DU MOIS
A5: INDICATEUR | B5: MOIS EN COURS | C5: MOIS PRÉCÉDENT | D5: ÉVOLUTION € | E5: ÉVOLUTION %
A6: Chiffre d'Affaires HT | B6: =SUMIFS(VENTES!F3:F476,VENTES!J3:J476,PARAMETRES!C16,VENTES!K3:K476,PARAMETRES!C14) -> 13706.27 | C6: =SUMIFS(VENTES!F3:F476,VENTES!J3:J476,IF(PARAMETRES!C16=1,12,PARAMETRES!C16-1),VENTES!K3:K476,IF(PARAMETRES!C16=1,PARAMETRES!C14-1,PARAMETRES!C14)) -> 23380.51 | D6: =B6-C6 -> -9674.24 | E6: =IF(C6>0,(B6-C6)/C6,0) -> -0.41377369
A7: Commission Totale | B7: =SUMIFS(VENTES!I3:I476,VENTES!J3:J476,PARAMETRES!C16,VENTES!K3:K476,PARAMETRES!C14) -> 685.3135 | C7: =SUMIFS(VENTES!I3:I476,VENTES!J3:J476,IF(PARAMETRES!C16=1,12,PARAMETRES!C16-1),VENTES!K3:K476,IF(PARAMETRES!C16=1,PARAMETRES!C14-1,PARAMETRES!C14)) -> 1235.3171 | D7: =B7-C7 -> -550.0036 | E7: =IF(C7>0,(B7-C7)/C7,0) -> -0.44523273
A8: Nombre BL Direct | B8: =COUNTIFS(VENTES!J3:J476,PARAMETRES!C16,VENTES!K3:K476,PARAMETRES!C14,VENTES!D3:D476,"Direct") -> 0 | C8: =COUNTIFS(VENTES!J3:J476,IF(PARAMETRES!C16=1,12,PARAMETRES!C16-1),VENTES!K3:K476,IF(PARAMETRES!C16=1,PARAMETRES!C14-1,PARAMETRES!C14),VENTES!D3:D476,"Direct") -> 7 | D8: =B8-C8 -> -7 | E8: =IF(C8>0,(B8-C8)/C8,0) -> -1
A9: Nombre BL Centrale | B9: =COUNTIFS(VENTES!J3:J476,PARAMETRES!C16,VENTES!K3:K476,PARAMETRES!C14,VENTES!D3:D476,"Centrale") -> 36 | C9: =COUNTIFS(VENTES!J3:J476,IF(PARAMETRES!C16=1,12,PARAMETRES!C16-1),VENTES!K3:K476,IF(PARAMETRES!C16=1,PARAMETRES!C14-1,PARAMETRES!C14),VENTES!D3:D476,"Centrale") -> 49 | D9: =B9-C9 -> -13 | E9: =IF(C9>0,(B9-C9)/C9,0) -> -0.26530612
A10: Nombre BL TOTAL | B10: =B8+B9 -> 36 | C10: =C8+C9 -> 56 | D10: =B10-C10 -> -20 | E10: =IF(C10>0,(B10-C10)/C10,0) -> -0.35714286
A11: Panier Moyen HT | B11: =IF(B10>0,B6/B10,0) -> 380.72972 | C11: =IF(C10>0,C6/C10,0) -> 417.50911 | D11: =B11-C11 -> -36.779385 | E11: =IF(C11>0,(B11-C11)/C11,0) -> -0.088092414
A14: 2. PERFORMANCE PAR AGENT
A15: AGENT | B15: CA DIRECT | C15: CA CENTRALE | D15: CA TOTAL | E15: COMM. TOTAL | F15: NB BL DIR | G15: NB BL CENT | H15: NB BL TOT | I15: PART CA en % | J15: AOV Direct | K15: AOV Central
A16: CAP FRAIS | B16: =SUMIFS(VENTES!F3:F476,VENTES!E3:E476,"CAP FRAIS",VENTES!D3:D476,"Direct",VENTES!J3:J476,PARAMETRES!C16,VENTES!K3:K476,PARAMETRES!C14) -> 0 | C16: =SUMIFS(VENTES!F3:F476,VENTES!E3:E476,"CAP FRAIS",VENTES!D3:D476,"Centrale",VENTES!J3:J476,PARAMETRES!C16,VENTES!K3:K476,PARAMETRES!C14) -> 8054.09 | D16: =B16+C16 -> 8054.09 | E16: =SUMIFS(VENTES!I3:I476,VENTES!E3:E476,"CAP FRAIS",VENTES!J3:J476,PARAMETRES!C16,VENTES!K3:K476,PARAMETRES!C14) -> 402.7045 | F16: =COUNTIFS(VENTES!E3:E476,"CAP FRAIS",VENTES!D3:D476,"Direct",VENTES!J3:J476,PARAMETRES!C16,VENTES!K3:K476,PARAMETRES!C14) -> 0 | G16: =COUNTIFS(VENTES!E3:E476,"CAP FRAIS",VENTES!D3:D476,"Centrale",VENTES!J3:J476,PARAMETRES!C16,VENTES!K3:K476,PARAMETRES!C14) -> 19 | H16: =F16+G16 -> 19 | I16: =IF($B$6>0,D16/$B$6,0) -> 0.58762085 | J16: =IF(F16>0,B16/F16,0) -> 0 | K16: =IF(G16>0,C16/G16,0) -> 423.89947
A17: BROCARD | B17: =SUMIFS(VENTES!F3:F476,VENTES!E3:E476,"BROCARD",VENTES!D3:D476,"Direct",VENTES!J3:J476,PARAMETRES!C16,VENTES!K3:K476,PARAMETRES!C14) -> 0 | C17: =SUMIFS(VENTES!F3:F476,VENTES!E3:E476,"BROCARD",VENTES!D3:D476,"Centrale",VENTES!J3:J476,PARAMETRES!C16,VENTES!K3:K476,PARAMETRES!C14) -> 5652.18 | D17: =B17+C17 -> 5652.18 | E17: =SUMIFS(VENTES!I3:I476,VENTES!E3:E476,"BROCARD",VENTES!J3:J476,PARAMETRES!C16,VENTES!K3:K476,PARAMETRES!C14) -> 282.609 | F17: =COUNTIFS(VENTES!E3:E476,"BROCARD",VENTES!D3:D476,"Direct",VENTES!J3:J476,PARAMETRES!C16,VENTES!K3:K476,PARAMETRES!C14) -> 0 | G17: =COUNTIFS(VENTES!E3:E476,"BROCARD",VENTES!D3:D476,"Centrale",VENTES!J3:J476,PARAMETRES!C16,VENTES!K3:K476,PARAMETRES!C14) -> 17 | H17: =F17+G17 -> 17 | I17: =IF($B$6>0,D17/$B$6,0) -> 0.41237915 | J17: =IF(F17>0,B17/F17,0) -> 0 | K17: =IF(G17>0,C17/G17,0) -> 332.48118
A18: GMA GROUP | B18: =SUMIFS(VENTES!F3:F476,VENTES!E3:E476,"GMA GROUP",VENTES!D3:D476,"Direct",VENTES!J3:J476,PARAMETRES!C16,VENTES!K3:K476,PARAMETRES!C14) -> 0 | C18: =SUMIFS(VENTES!F3:F476,VENTES!E3:E476,"GMA GROUP",VENTES!D3:D476,"Centrale",VENTES!J3:J476,PARAMETRES!C16,VENTES!K3:K476,PARAMETRES!C14) -> 0 | D18: =B18+C18 -> 0 | E18: =SUMIFS(VENTES!I3:I476,VENTES!E3:E476,"GMA GROUP",VENTES!J3:J476,PARAMETRES!C16,VENTES!K3:K476,PARAMETRES!C14) -> 0 | F18: =COUNTIFS(VENTES!E3:E476,"GMA GROUP",VENTES!D3:D476,"Direct",VENTES!J3:J476,PARAMETRES!C16,VENTES!K3:K476,PARAMETRES!C14) -> 0 | G18: =COUNTIFS(VENTES!E3:E476,"GMA GROUP",VENTES!D3:D476,"Centrale",VENTES!J3:J476,PARAMETRES!C16,VENTES!K3:K476,PARAMETRES!C14) -> 0 | H18: =F18+G18 -> 0 | I18: =IF($B$6>0,D18/$B$6,0) -> 0 | J18: =IF(F18>0,B18/F18,0) -> 0 | K18: =IF(G18>0,C18/G18,0) -> 0
A19: SCHLESSER | B19: =SUMIFS(VENTES!F3:F476,VENTES!E3:E476,"SCHLESSER",VENTES!D3:D476,"Direct",VENTES!J3:J476,PARAMETRES!C16,VENTES!K3:K476,PARAMETRES!C14) -> 0 | C19: =SUMIFS(VENTES!F3:F476,VENTES!E3:E476,"SCHLESSER",VENTES!D3:D476,"Centrale",VENTES!J3:J476,PARAMETRES!C16,VENTES!K3:K476,PARAMETRES!C14) -> 0 | D19: =B19+C19 -> 0 | E19: =SUMIFS(VENTES!I3:I476,VENTES!E3:E476,"SCHLESSER",VENTES!J3:J476,PARAMETRES!C16,VENTES!K3:K476,PARAMETRES!C14) -> 0 | F19: =COUNTIFS(VENTES!E3:E476,"SCHLESSER",VENTES!D3:D476,"Direct",VENTES!J3:J476,PARAMETRES!C16,VENTES!K3:K476,PARAMETRES!C14) -> 0 | G19: =COUNTIFS(VENTES!E3:E476,"SCHLESSER",VENTES!D3:D476,"Centrale",VENTES!J3:J476,PARAMETRES!C16,VENTES!K3:K476,PARAMETRES!C14) -> 0 | H19: =F19+G19 -> 0 | I19: =IF($B$6>0,D19/$B$6,0) -> 0 | J19: =IF(F19>0,B19/F19,0) -> 0 | K19: =IF(G19>0,C19/G19,0) -> 0
A20: TOTAL | B20: =SUM(B16:B19) -> 0 | C20: =SUM(C16:C19) -> 13706.27 | D20: =SUM(D16:D19) -> 13706.27 | E20: =SUM(E16:E19) -> 685.3135 | F20: =SUM(F16:F19) -> 0 | G20: =SUM(G16:G19) -> 36 | H20: =SUM(H16:H19) -> 36 | I20: =SUM(I16:I19) -> 1 | J20: =IF(F20>0,B20/F20,0) -> 0 | K20: =IF(G20>0,C20/G20,0) -> 380.72972
A23: 3. FOCUS ENSEIGNES CENTRALES
A24: AGENT | B24: 45962 | C24: 45992 | D24: Jan 2026 | E24: Fév | F24: Mar | G24: Avr | H24: Mai | I24: Jun | J24: Jul | K24: Aoû | L24: Sep | M24: Oct | N24: Nov | O24: Déc
A25: CAP FRAIS | B25: =IFERROR( SUMIFS( VENTES!F:F , VENTES!E:E , $A25 , VENTES!D:D , "Centrale" , VENTES!J:J , B$30 , VENTES!K:K , B$29 ), 0) -> 0 | C25: =IFERROR(SUMIFS(VENTES!F:F,VENTES!E:E,$A25,VENTES!D:D,"Centrale",VENTES!J:J,12,VENTES!K:K,2025),0) -> 1563.68 | D25: =IFERROR(SUMIFS(VENTES!F:F,VENTES!E:E,$A31,VENTES!D:D,"Centrale",VENTES!J:J,1,VENTES!K:K,2026),0) -> 6968.75 | E25: =IFERROR(SUMIFS(VENTES!F:F,VENTES!E:E,$A31,VENTES!D:D,"Centrale",VENTES!J:J,2,VENTES!K:K,2026),0) -> 13276.37 | F25: =IFERROR(SUMIFS(VENTES!F:F,VENTES!E:E,$A31,VENTES!D:D,"Centrale",VENTES!J:J,3,VENTES!K:K,2026),0) -> 7770.78 | G25: =IFERROR(SUMIFS(VENTES!F:F,VENTES!E:E,$A31,VENTES!D:D,"Centrale",VENTES!J:J,4,VENTES!K:K,2026),0) -> 11071.21 | H25: =IFERROR(SUMIFS(VENTES!F:F,VENTES!E:E,$A31,VENTES!D:D,"Centrale",VENTES!J:J,5,VENTES!K:K,2026),0) -> 11974.45 | I25: =IFERROR(SUMIFS(VENTES!F:F,VENTES!E:E,$A31,VENTES!D:D,"Centrale",VENTES!J:J,6,VENTES!K:K,2026),0) -> 11557.54 | J25: =IFERROR(SUMIFS(VENTES!F:F,VENTES!E:E,$A31,VENTES!D:D,"Centrale",VENTES!J:J,7,VENTES!K:K,2026),0) -> 12388.97 | K25: =IFERROR(SUMIFS(VENTES!F:F,VENTES!E:E,$A31,VENTES!D:D,"Centrale",VENTES!J:J,8,VENTES!K:K,2026),0) -> 9854.86 | L25: =IFERROR(SUMIFS(VENTES!F:F,VENTES!E:E,$A31,VENTES!D:D,"Centrale",VENTES!J:J,9,VENTES!K:K,2026),0) -> 0 | M25: =IFERROR(SUMIFS(VENTES!F:F,VENTES!E:E,$A31,VENTES!D:D,"Centrale",VENTES!J:J,10,VENTES!K:K,2026),0) -> 0 | N25: =IFERROR(SUMIFS(VENTES!F:F,VENTES!E:E,$A31,VENTES!D:D,"Centrale",VENTES!J:J,11,VENTES!K:K,2026),0) -> 0 | O25: =IFERROR(SUMIFS(VENTES!F:F,VENTES!E:E,$A31,VENTES!D:D,"Centrale",VENTES!J:J,12,VENTES!K:K,2026),0) -> 0
A26: BROCARD | B26: =IFERROR(SUMIFS(VENTES!F:F,VENTES!E:E,$A26,VENTES!D:D,"Centrale",VENTES!J:J,11,VENTES!K:K,2025),0) -> 0 | C26: =IFERROR(SUMIFS(VENTES!F:F,VENTES!E:E,$A26,VENTES!D:D,"Centrale",VENTES!J:J,12,VENTES!K:K,2025),0) -> 0 | D26: =IFERROR(SUMIFS(VENTES!F:F,VENTES!E:E,$A26,VENTES!D:D,"Centrale",VENTES!J:J,1,VENTES!K:K,2026),0) -> 8417.95 | E26: =IFERROR(SUMIFS(VENTES!F:F,VENTES!E:E,$A26,VENTES!D:D,"Centrale",VENTES!J:J,2,VENTES!K:K,2026),0) -> 9309.7 | F26: =IFERROR(SUMIFS(VENTES!F:F,VENTES!E:E,$A26,VENTES!D:D,"Centrale",VENTES!J:J,3,VENTES!K:K,2026),0) -> 8293.01 | G26: =IFERROR(SUMIFS(VENTES!F:F,VENTES!E:E,$A26,VENTES!D:D,"Centrale",VENTES!J:J,4,VENTES!K:K,2026),0) -> 9736.2 | H26: =IFERROR(SUMIFS(VENTES!$F:$F,VENTES!$E:$E,$A26,VENTES!$D:$D,"Centrale",VENTES!$J:$J,5,VENTES!$K:$K,2026),0) -> 9266.62 | I26: =IFERROR(SUMIFS(VENTES!$F:$F,VENTES!$E:$E,$A26,VENTES!$D:$D,"Centrale",VENTES!$J:$J,6,VENTES!$K:$K,2026),0) -> 7022.91 | J26: =IFERROR(SUMIFS(VENTES!$F:$F,VENTES!$E:$E,$A26,VENTES!$D:$D,"Centrale",VENTES!$J:$J,7,VENTES!$K:$K,2026),0) -> 7676.96 | K26: =IFERROR(SUMIFS(VENTES!$F:$F,VENTES!$E:$E,$A26,VENTES!$D:$D,"Centrale",VENTES!$J:$J,8,VENTES!$K:$K,2026),0) -> 5652.18 | L26: =IFERROR(SUMIFS(VENTES!$F:$F,VENTES!$E:$E,$A26,VENTES!$D:$D,"Centrale",VENTES!$J:$J,9,VENTES!$K:$K,2026),0) -> 0 | M26: =IFERROR(SUMIFS(VENTES!$F:$F,VENTES!$E:$E,$A26,VENTES!$D:$D,"Centrale",VENTES!$J:$J,10,VENTES!$K:$K,2026),0) -> 0 | N26: =IFERROR(SUMIFS(VENTES!$F:$F,VENTES!$E:$E,$A26,VENTES!$D:$D,"Centrale",VENTES!$J:$J,11,VENTES!$K:$K,2026),0) -> 0 | O26: =IFERROR(SUMIFS(VENTES!$F:$F,VENTES!$E:$E,$A26,VENTES!$D:$D,"Centrale",VENTES!$J:$J,12,VENTES!$K:$K,2026),0) -> 0
A27: GMA GROUP | B27: =IFERROR(SUMIFS(VENTES!F:F,VENTES!E:E,$A27,VENTES!D:D,"Centrale",VENTES!J:J,11,VENTES!K:K,2025),0) -> 0 | C27: =IFERROR(SUMIFS(VENTES!F:F,VENTES!E:E,$A27,VENTES!D:D,"Centrale",VENTES!J:J,12,VENTES!K:K,2025),0) -> 0 | D27: =IFERROR(SUMIFS(VENTES!F:F,VENTES!E:E,$A27,VENTES!D:D,"Centrale",VENTES!J:J,1,VENTES!K:K,2026),0) -> 6238.4 | E27: =IFERROR(SUMIFS(VENTES!F:F,VENTES!E:E,$A27,VENTES!D:D,"Centrale",VENTES!J:J,2,VENTES!K:K,2026),0) -> 10346.24 | F27: =IFERROR(SUMIFS(VENTES!F:F,VENTES!E:E,$A27,VENTES!D:D,"Centrale",VENTES!J:J,3,VENTES!K:K,2026),0) -> 6774.4 | G27: =IFERROR(SUMIFS(VENTES!F:F,VENTES!E:E,$A27,VENTES!D:D,"Centrale",VENTES!J:J,4,VENTES!K:K,2026),0) -> 8041.6 | H27: =IFERROR(SUMIFS(VENTES!F:F,VENTES!E:E,$A27,VENTES!D:D,"Centrale",VENTES!J:J,5,VENTES!K:K,2026),0) -> 5763.2 | I27: =IFERROR(SUMIFS(VENTES!F:F,VENTES!E:E,$A27,VENTES!D:D,"Centrale",VENTES!J:J,6,VENTES!K:K,2026),0) -> 0 | J27: =IFERROR(SUMIFS(VENTES!F:F,VENTES!E:E,$A27,VENTES!D:D,"Centrale",VENTES!J:J,7,VENTES!K:K,2026),0) -> 0 | K27: =IFERROR(SUMIFS(VENTES!F:F,VENTES!E:E,$A27,VENTES!D:D,"Centrale",VENTES!J:J,8,VENTES!K:K,2026),0) -> 0 | L27: =IFERROR(SUMIFS(VENTES!F:F,VENTES!E:E,$A27,VENTES!D:D,"Centrale",VENTES!J:J,9,VENTES!K:K,2026),0) -> 0 | M27: =IFERROR(SUMIFS(VENTES!F:F,VENTES!E:E,$A27,VENTES!D:D,"Centrale",VENTES!J:J,10,VENTES!K:K,2026),0) -> 0 | N27: =IFERROR(SUMIFS(VENTES!F:F,VENTES!E:E,$A27,VENTES!D:D,"Centrale",VENTES!J:J,11,VENTES!K:K,2026),0) -> 0 | O27: =IFERROR(SUMIFS(VENTES!F:F,VENTES!E:E,$A27,VENTES!D:D,"Centrale",VENTES!J:J,12,VENTES!K:K,2026),0) -> 0
A29: 4. FOCUS ENSEIGNES DIRECTS
A30: AGENT | B30: 45962 | C30: 45992 | D30: Jan 2026 | E30: Fév | F30: Mar | G30: Avr | H30: Mai | I30: Jun | J30: Jul | K30: Aoû | L30: Sep | M30: Oct | N30: Nov | O30: Déc
A31: CAP FRAIS | B31: =IFERROR(SUMIFS(VENTES!F:F,VENTES!E:E,$A31,VENTES!D:D,"Direct",VENTES!J:J,11,VENTES!K:K,2025),0) -> 6065.56 | C31: =IFERROR(SUMIFS(VENTES!F:F,VENTES!E:E,$A31,VENTES!D:D,"Direct",VENTES!J:J,12,VENTES!K:K,2025),0) -> 1271.36 | D31: =IFERROR(SUMIFS(VENTES!F:F,VENTES!E:E,$A31,VENTES!D:D,"Direct",VENTES!J:J,1,VENTES!K:K,2026),0) -> 3983.52 | E31: =IFERROR(SUMIFS(VENTES!F:F,VENTES!E:E,$A31,VENTES!D:D,"Direct",VENTES!J:J,2,VENTES!K:K,2026),0) -> 4728.16 | F31: =IFERROR(SUMIFS(VENTES!F:F,VENTES!E:E,$A31,VENTES!D:D,"Direct",VENTES!J:J,3,VENTES!K:K,2026),0) -> 3755.15 | G31: =IFERROR(SUMIFS(VENTES!F:F,VENTES!E:E,$A31,VENTES!D:D,"Direct",VENTES!J:J,4,VENTES!K:K,2026),0) -> 2333.92 | H31: =IFERROR(SUMIFS(VENTES!F:F,VENTES!E:E,$A31,VENTES!D:D,"Direct",VENTES!J:J,5,VENTES!K:K,2026),0) -> 3020.64 | I31: =IFERROR(SUMIFS(VENTES!F:F,VENTES!E:E,$A31,VENTES!D:D,"Direct",VENTES!J:J,6,VENTES!K:K,2026),0) -> 2589.81 | J31: =IFERROR(SUMIFS(VENTES!F:F,VENTES!E:E,$A31,VENTES!D:D,"Direct",VENTES!J:J,7,VENTES!K:K,2026),0) -> 3314.58 | K31: =IFERROR(SUMIFS(VENTES!F:F,VENTES!E:E,$A31,VENTES!D:D,"Direct",VENTES!J:J,8,VENTES!K:K,2026),0) -> 436.16 | L31: =IFERROR(SUMIFS(VENTES!F:F,VENTES!E:E,$A31,VENTES!D:D,"Direct",VENTES!J:J,9,VENTES!K:K,2026),0) -> 0 | M31: =IFERROR(SUMIFS(VENTES!F:F,VENTES!E:E,$A31,VENTES!D:D,"Direct",VENTES!J:J,10,VENTES!K:K,2026),0) -> 0 | N31: =IFERROR(SUMIFS(VENTES!F:F,VENTES!E:E,$A31,VENTES!D:D,"Direct",VENTES!J:J,11,VENTES!K:K,2026),0) -> 0 | O31: =IFERROR(SUMIFS(VENTES!F:F,VENTES!E:E,$A31,VENTES!D:D,"Direct",VENTES!J:J,12,VENTES!K:K,2026),0) -> 0
A32: BROCARD | B32: =IFERROR(SUMIFS(VENTES!F:F,VENTES!E:E,$A32,VENTES!D:D,"Direct",VENTES!J:J,11,VENTES!K:K,2025),0) -> 0 | C32: =IFERROR(SUMIFS(VENTES!F:F,VENTES!E:E,$A32,VENTES!D:D,"Direct",VENTES!J:J,12,VENTES!K:K,2025),0) -> 0 | D32: =IFERROR(SUMIFS(VENTES!F:F,VENTES!E:E,$A32,VENTES!D:D,"Direct",VENTES!J:J,1,VENTES!K:K,2026),0) -> 0 | E32: =IFERROR(SUMIFS(VENTES!F:F,VENTES!E:E,$A32,VENTES!D:D,"Direct",VENTES!J:J,2,VENTES!K:K,2026),0) -> 2630.88 | F32: =IFERROR(SUMIFS(VENTES!F:F,VENTES!E:E,$A32,VENTES!D:D,"Direct",VENTES!J:J,3,VENTES!K:K,2026),0) -> 974.4 | G32: =IFERROR(SUMIFS(VENTES!F:F,VENTES!E:E,$A32,VENTES!D:D,"Direct",VENTES!J:J,4,VENTES!K:K,2026),0) -> 1893.12 | H32: =IFERROR(SUMIFS(VENTES!F:F,VENTES!E:E,$A32,VENTES!D:D,"Direct",VENTES!J:J,5,VENTES!K:K,2026),0) -> 951.2 | I32: =IFERROR(SUMIFS(VENTES!F:F,VENTES!E:E,$A32,VENTES!D:D,"Direct",VENTES!J:J,6,VENTES!K:K,2026),0) -> 0 | J32: =IFERROR(SUMIFS(VENTES!F:F,VENTES!E:E,$A32,VENTES!D:D,"Direct",VENTES!J:J,7,VENTES!K:K,2026),0) -> 0 | K32: =IFERROR(SUMIFS(VENTES!F:F,VENTES!E:E,$A32,VENTES!D:D,"Direct",VENTES!J:J,8,VENTES!K:K,2026),0) -> 0 | L32: =IFERROR(SUMIFS(VENTES!F:F,VENTES!E:E,$A32,VENTES!D:D,"Direct",VENTES!J:J,9,VENTES!K:K,2026),0) -> 0 | M32: =IFERROR(SUMIFS(VENTES!F:F,VENTES!E:E,$A32,VENTES!D:D,"Direct",VENTES!J:J,10,VENTES!K:K,2026),0) -> 0 | N32: =IFERROR(SUMIFS(VENTES!F:F,VENTES!E:E,$A32,VENTES!D:D,"Direct",VENTES!J:J,11,VENTES!K:K,2026),0) -> 0 | O32: =IFERROR(SUMIFS(VENTES!F:F,VENTES!E:E,$A32,VENTES!D:D,"Direct",VENTES!J:J,12,VENTES!K:K,2026),0) -> 0
A33: SCHLESSER | B33: =IFERROR(SUMIFS(VENTES!F:F,VENTES!E:E,$A33,VENTES!D:D,"Direct",VENTES!J:J,11,VENTES!K:K,2025),0) -> 0 | C33: =IFERROR(SUMIFS(VENTES!F:F,VENTES!E:E,$A33,VENTES!D:D,"Direct",VENTES!J:J,12,VENTES!K:K,2025),0) -> 0 | D33: =IFERROR(SUMIFS(VENTES!F:F,VENTES!E:E,$A33,VENTES!D:D,"Direct",VENTES!J:J,1,VENTES!K:K,2026),0) -> 1364.16 | E33: =IFERROR(SUMIFS(VENTES!F:F,VENTES!E:E,$A33,VENTES!D:D,"Direct",VENTES!J:J,2,VENTES!K:K,2026),0) -> 1155.36 | F33: =IFERROR(SUMIFS(VENTES!F:F,VENTES!E:E,$A33,VENTES!D:D,"Direct",VENTES!J:J,3,VENTES!K:K,2026),0) -> 941.92 | G33: =IFERROR(SUMIFS(VENTES!F:F,VENTES!E:E,$A33,VENTES!D:D,"Direct",VENTES!J:J,4,VENTES!K:K,2026),0) -> 1763.2 | H33: =IFERROR(SUMIFS(VENTES!F:F,VENTES!E:E,$A33,VENTES!D:D,"Direct",VENTES!J:J,5,VENTES!K:K,2026),0) -> 0 | I33: =IFERROR(SUMIFS(VENTES!F:F,VENTES!E:E,$A33,VENTES!D:D,"Direct",VENTES!J:J,6,VENTES!K:K,2026),0) -> 0 | J33: =IFERROR(SUMIFS(VENTES!F:F,VENTES!E:E,$A33,VENTES!D:D,"Direct",VENTES!J:J,7,VENTES!K:K,2026),0) -> 0 | K33: =IFERROR(SUMIFS(VENTES!F:F,VENTES!E:E,$A33,VENTES!D:D,"Direct",VENTES!J:J,8,VENTES!K:K,2026),0) -> 0 | L33: =IFERROR(SUMIFS(VENTES!F:F,VENTES!E:E,$A33,VENTES!D:D,"Direct",VENTES!J:J,9,VENTES!K:K,2026),0) -> 0 | M33: =IFERROR(SUMIFS(VENTES!F:F,VENTES!E:E,$A33,VENTES!D:D,"Direct",VENTES!J:J,10,VENTES!K:K,2026),0) -> 0 | N33: =IFERROR(SUMIFS(VENTES!F:F,VENTES!E:E,$A33,VENTES!D:D,"Direct",VENTES!J:J,11,VENTES!K:K,2026),0) -> 0 | O33: =IFERROR(SUMIFS(VENTES!F:F,VENTES!E:E,$A33,VENTES!D:D,"Direct",VENTES!J:J,12,VENTES!K:K,2026),0) -> 0
A36: 5. ÉVOLUTION SUR 12 MOIS
A37: INDICATEUR | B37: Jan | C37: Fév | D37: Mar | E37: Avr | F37: Mai | G37: Jun | H37: Jul | I37: Aoû | J37: Sep | K37: Oct | L37: Nov | M37: Déc
A38: CA TOTAL (€) | B38: =SUMIFS(VENTES!F3:F476,VENTES!J3:J476,1,VENTES!K3:K476,PARAMETRES!C14) -> 26972.78 | C38: =SUMIFS(VENTES!F3:F476,VENTES!J3:J476,2,VENTES!K3:K476,PARAMETRES!C14) -> 41446.71 | D38: =SUMIFS(VENTES!F3:F476,VENTES!J3:J476,3,VENTES!K3:K476,PARAMETRES!C14) -> 28509.66 | E38: =SUMIFS(VENTES!F3:F476,VENTES!J3:J476,4,VENTES!K3:K476,PARAMETRES!C14) -> 34839.25 | F38: =SUMIFS(VENTES!F3:F476,VENTES!J3:J476,5,VENTES!K3:K476,PARAMETRES!C14) -> 30976.11 | G38: =SUMIFS(VENTES!F3:F476,VENTES!J3:J476,6,VENTES!K3:K476,PARAMETRES!C14) -> 21170.26 | H38: =SUMIFS(VENTES!F3:F476,VENTES!J3:J476,7,VENTES!K3:K476,PARAMETRES!C14) -> 23380.51 | I38: =SUMIFS(VENTES!F3:F476,VENTES!J3:J476,8,VENTES!K3:K476,PARAMETRES!C14) -> 13706.27 | J38: =SUMIFS(VENTES!F3:F476,VENTES!J3:J476,9,VENTES!K3:K476,PARAMETRES!C14) -> 0 | K38: =SUMIFS(VENTES!F3:F476,VENTES!J3:J476,10,VENTES!K3:K476,PARAMETRES!C14) -> 0 | L38: =SUMIFS(VENTES!F3:F476,VENTES!J3:J476,11,VENTES!K3:K476,PARAMETRES!C14) -> 0 | M38: =SUMIFS(VENTES!F3:F476,VENTES!J3:J476,12,VENTES!K3:K476,PARAMETRES!C14) -> 0
A39: COMMISSION (€) | B39: =SUMIFS(VENTES!I3:I476,VENTES!J3:J476,1,VENTES!K3:K476,PARAMETRES!C14) -> 1455.5926 | C39: =SUMIFS(VENTES!I3:I476,VENTES!J3:J476,2,VENTES!K3:K476,PARAMETRES!C14) -> 2242.6235 | D39: =SUMIFS(VENTES!I3:I476,VENTES!J3:J476,3,VENTES!K3:K476,PARAMETRES!C14) -> 1538.9124 | E39: =SUMIFS(VENTES!I3:I476,VENTES!J3:J476,4,VENTES!K3:K476,PARAMETRES!C14) -> 1861.7673 | F39: =SUMIFS(VENTES!I3:I476,VENTES!J3:J476,5,VENTES!K3:K476,PARAMETRES!C14) -> 1628.2423 | G39: =SUMIFS(VENTES!I3:I476,VENTES!J3:J476,6,VENTES!K3:K476,PARAMETRES!C14) -> 1110.3092 | H39: =SUMIFS(VENTES!I3:I476,VENTES!J3:J476,7,VENTES!K3:K476,PARAMETRES!C14) -> 1235.3171 | I39: =SUMIFS(VENTES!I3:I476,VENTES!J3:J476,8,VENTES!K3:K476,PARAMETRES!C14) -> 685.3135 | J39: =SUMIFS(VENTES!I3:I476,VENTES!J3:J476,9,VENTES!K3:K476,PARAMETRES!C14) -> 0 | K39: =SUMIFS(VENTES!I3:I476,VENTES!J3:J476,10,VENTES!K3:K476,PARAMETRES!C14) -> 0 | L39: =SUMIFS(VENTES!I3:I476,VENTES!J3:J476,11,VENTES!K3:K476,PARAMETRES!C14) -> 0 | M39: =SUMIFS(VENTES!I3:I476,VENTES!J3:J476,12,VENTES!K3:K476,PARAMETRES!C14) -> 0
A40: NB BL | B40: =COUNTIFS(VENTES!J3:J476,1,VENTES!K3:K476,PARAMETRES!C14) -> 61 | C40: =COUNTIFS(VENTES!J3:J476,2,VENTES!K3:K476,PARAMETRES!C14) -> 68 | D40: =COUNTIFS(VENTES!J3:J476,3,VENTES!K3:K476,PARAMETRES!C14) -> 56 | E40: =COUNTIFS(VENTES!J3:J476,4,VENTES!K3:K476,PARAMETRES!C14) -> 66 | F40: =COUNTIFS(VENTES!J3:J476,5,VENTES!K3:K476,PARAMETRES!C14) -> 57 | G40: =COUNTIFS(VENTES!J3:J476,6,VENTES!K3:K476,PARAMETRES!C14) -> 51 | H40: =COUNTIFS(VENTES!J3:J476,7,VENTES!K3:K476,PARAMETRES!C14) -> 56 | I40: =COUNTIFS(VENTES!J3:J476,8,VENTES!K3:K476,PARAMETRES!C14) -> 36 | J40: =COUNTIFS(VENTES!J3:J476,9,VENTES!K3:K476,PARAMETRES!C14) -> 0 | K40: =COUNTIFS(VENTES!J3:J476,10,VENTES!K3:K476,PARAMETRES!C14) -> 0 | L40: =COUNTIFS(VENTES!J3:J476,11,VENTES!K3:K476,PARAMETRES!C14) -> 0 | M40: =COUNTIFS(VENTES!J3:J476,12,VENTES!K3:K476,PARAMETRES!C14) -> 0
B42: Jan | C42: Fév | D42: Mar | E42: Avr | F42: Mai | G42: Jun | H42: Jul | I42: Aoû | J42: Sep | K42: Oct | L42: Nov | M42: Déc
A43: SCACHAP
A44: OTERA SAS
A45: SCAOUEST
A46: ALDOUEST
A47: SCADIF

Sheet SUIVI CLIENTS
A2: SUIVI FIDÉLISATION CLIENT
A3: Enseignes Fidèles:
A4: Nouveaux Clients:
A5: Récurrence Moyenne:
A6: Pattern 2-3 mois:
A7: ⚠️ Clients à Relancer: | B7: Voir liste ci-dessous
A10: LISTE DÉTAILLÉE DES ENSEIGNES
A11: ENSEIGNE | B11: AGENT | C11: TYPE | D11: NB BL TOTAL | E11: CA TOTAL | F11: DERNIÈRE CMD | G11: MOIS SANS CMD | H11: RÉCURRENCE | I11: STATUTS | J11: ACTION
A12: {=UNIQUE(SORT(VENTES!C3:C1000))} -> ALDOUEST | B12: =IFERROR(VLOOKUP($A12,VENTES!$C:E,3,FALSE),"") -> CAP FRAIS | C12: =IFERROR(VLOOKUP($A12,VENTES!C:E,2,FALSE()),"") -> Centrale | D12: =COUNTIF(VENTES!$C:$C,$A12) -> 8 | E12: =SUMIF(VENTES!$C:$C,$A12,VENTES!$F:$F) -> 3699.5 | F12: =IFERROR(__xludf.DUMMYFUNCTION("IFERROR(MAX(FILTER(VENTES!$A:$A,VENTES!$C:$C=$A12)),"""")"),46253.0) -> 46253 | G12: =IF(F12="","",DATEDIF(F12,TODAY(),"M")) -> 1 | H12: =IFERROR(__xludf.DUMMYFUNCTION("IF(D12=0,0,D12 /MONTH(COUNTUNIQUE(FILTRE(VENTES!$A:$A,VENTES!$C:$C=$A12))) )"),0.6666666666666666) -> 0.66666667 | I12: =IF(G12="","",IF(G12 > PARAMETRES!B15,"À RELANCER","OK")) -> À RELANCER
A13: AUCHAN HYPERMARCHE AVRILLE - SAS JUIGNEDIS (SAS) | B13: =IFERROR(VLOOKUP($A13,VENTES!$C:E,3,FALSE),"") -> CAP FRAIS | C13: =IFERROR(VLOOKUP($A13,VENTES!C:E,2,FALSE()),"") -> Direct | D13: =COUNTIF(VENTES!$C:$C,$A13) -> 1 | E13: =SUMIF(VENTES!$C:$C,$A13,VENTES!$F:$F) -> 412.96 | F13: =IFERROR(__xludf.DUMMYFUNCTION("IFERROR(MAX(FILTER(VENTES!$A:$A,VENTES!$C:$C=$A13)),"""")"),45981.0) -> 45981 | G13: =IF(F13="","",DATEDIF(F13,TODAY(),"M")) -> 10 | H13: =IFERROR(__xludf.DUMMYFUNCTION("IF(D13=0,0,D13 /MONTH(COUNTUNIQUE(FILTRE(VENTES!$A:$A,VENTES!$C:$C=$A13))) )"),0.08333333333333333) -> 0.083333333 | I13: =IF(G13="","",IF(G13 > PARAMETRES!B16,"À RELANCER","OK")) -> OK
A14: CARREFOUR BELGIQUE | B14: =IFERROR(VLOOKUP($A14,VENTES!$C:E,3,FALSE),"") -> GMA GROUP | C14: =IFERROR(VLOOKUP($A14,VENTES!C:E,2,FALSE()),"") -> Centrale | D14: =COUNTIF(VENTES!$C:$C,$A14) -> 28 | E14: =SUMIF(VENTES!$C:$C,$A14,VENTES!$F:$F) -> 37163.84 | F14: =IFERROR(__xludf.DUMMYFUNCTION("IFERROR(MAX(FILTER(VENTES!$A:$A,VENTES!$C:$C=$A14)),"""")"),46168.0) -> 46168 | G14: =IF(F14="","",DATEDIF(F14,TODAY(),"M")) -> 3 | H14: =IFERROR(__xludf.DUMMYFUNCTION("IF(D14=0,0,D14 /MONTH(COUNTUNIQUE(FILTRE(VENTES!$A:$A,VENTES!$C:$C=$A14))) )"),2.3333333333333335) -> 2.3333333 | I14: =IF(G14="","",IF(G14 > PARAMETRES!B17,"À RELANCER","OK")) -> À RELANCER
A15: E. LECLERC PONTCHATEAU (SAS) | B15: =IFERROR(VLOOKUP($A15,VENTES!$C:E,3,FALSE),"") -> CAP FRAIS | C15: =IFERROR(VLOOKUP($A15,VENTES!C:E,2,FALSE()),"") -> Direct | D15: =COUNTIF(VENTES!$C:$C,$A15) -> 3 | E15: =SUMIF(VENTES!$C:$C,$A15,VENTES!$F:$F) -> 2811.84 | F15: =IFERROR(__xludf.DUMMYFUNCTION("IFERROR(MAX(FILTER(VENTES!$A:$A,VENTES!$C:$C=$A15)),"""")"),46155.0) -> 46155 | G15: =IF(F15="","",DATEDIF(F15,TODAY(),"M")) -> 4 | H15: =IFERROR(__xludf.DUMMYFUNCTION("IF(D15=0,0,D15 /MONTH(COUNTUNIQUE(FILTRE(VENTES!$A:$A,VENTES!$C:$C=$A15))) )"),0.25) -> 0.25 | I15: =IF(G15="","",IF(G15 > PARAMETRES!B18,"À RELANCER","OK")) -> OK
A16: HYPER U ST PHILBERT DE GRANDLIEU- PHILDIS SAS - | B16: =IFERROR(VLOOKUP($A16,VENTES!$C:E,3,FALSE),"") -> CAP FRAIS | C16: =IFERROR(VLOOKUP($A16,VENTES!C:E,2,FALSE()),"") -> Direct | D16: =COUNTIF(VENTES!$C:$C,$A16) -> 1 | E16: =SUMIF(VENTES!$C:$C,$A16,VENTES!$F:$F) -> 389.76 | F16: =IFERROR(__xludf.DUMMYFUNCTION("IFERROR(MAX(FILTER(VENTES!$A:$A,VENTES!$C:$C=$A16)),"""")"),46072.0) -> 46072 | G16: =IF(F16="","",DATEDIF(F16,TODAY(),"M")) -> 7 | H16: =IFERROR(__xludf.DUMMYFUNCTION("IF(D16=0,0,D16 /MONTH(COUNTUNIQUE(FILTRE(VENTES!$A:$A,VENTES!$C:$C=$A16))) )"),0.08333333333333333) -> 0.083333333 | I16: =IF(G16="","",IF(G16 > PARAMETRES!B19,"À RELANCER","OK")) -> OK
A17: HYPER U -Savenay (SAS) | B17: =IFERROR(VLOOKUP($A17,VENTES!$C:E,3,FALSE),"") -> CAP FRAIS | C17: =IFERROR(VLOOKUP($A17,VENTES!C:E,2,FALSE()),"") -> Direct | D17: =COUNTIF(VENTES!$C:$C,$A17) -> 4 | E17: =SUMIF(VENTES!$C:$C,$A17,VENTES!$F:$F) -> 1763.2 | F17: =IFERROR(__xludf.DUMMYFUNCTION("IFERROR(MAX(FILTER(VENTES!$A:$A,VENTES!$C:$C=$A17)),"""")"),46104.0) -> 46104 | G17: =IF(F17="","",DATEDIF(F17,TODAY(),"M")) -> 5 | H17: =IFERROR(__xludf.DUMMYFUNCTION("IF(D17=0,0,D17 /MONTH(COUNTUNIQUE(FILTRE(VENTES!$A:$A,VENTES!$C:$C=$A17))) )"),0.3333333333333333) -> 0.33333333 | I17: =IF(G17="","",IF(G17 > PARAMETRES!B20,"À RELANCER","OK")) -> OK
A18: HYPER U LA MONTAGNE- SARL SODISUD | B18: =IFERROR(VLOOKUP($A18,VENTES!$C:E,3,FALSE),"") -> CAP FRAIS | C18: =IFERROR(VLOOKUP($A18,VENTES!C:E,2,FALSE()),"") -> Direct | D18: =COUNTIF(VENTES!$C:$C,$A18) -> 1 | E18: =SUMIF(VENTES!$C:$C,$A18,VENTES!$F:$F) -> 389.76 | F18: =IFERROR(__xludf.DUMMYFUNCTION("IFERROR(MAX(FILTER(VENTES!$A:$A,VENTES!$C:$C=$A18)),"""")"),46070.0) -> 46070 | G18: =IF(F18="","",DATEDIF(F18,TODAY(),"M")) -> 7 | H18: =IFERROR(__xludf.DUMMYFUNCTION("IF(D18=0,0,D18 /MONTH(COUNTUNIQUE(FILTRE(VENTES!$A:$A,VENTES!$C:$C=$A18))) )"),0.08333333333333333) -> 0.083333333 | I18: =IF(G18="","",IF(G18 > PARAMETRES!B21,"À RELANCER","OK")) -> OK
A19: HYPER U LES HERBIERS ( SAS EXAGONE) | B19: =IFERROR(VLOOKUP($A19,VENTES!$C:E,3,FALSE),"") -> CAP FRAIS | C19: =IFERROR(VLOOKUP($A19,VENTES!C:E,2,FALSE()),"") -> Direct | D19: =COUNTIF(VENTES!$C:$C,$A19) -> 4 | E19: =SUMIF(VENTES!$C:$C,$A19,VENTES!$F:$F) -> 2060.16 | F19: =IFERROR(__xludf.DUMMYFUNCTION("IFERROR(MAX(FILTER(VENTES!$A:$A,VENTES!$C:$C=$A19)),"""")"),46106.0) -> 46106 | G19: =IF(F19="","",DATEDIF(F19,TODAY(),"M")) -> 5 | H19: =IFERROR(__xludf.DUMMYFUNCTION("IF(D19=0,0,D19 /MONTH(COUNTUNIQUE(FILTRE(VENTES!$A:$A,VENTES!$C:$C=$A19))) )"),0.3333333333333333) -> 0.33333333 | I19: =IF(G19="","",IF(G19 > PARAMETRES!B22,"À RELANCER","OK")) -> À RELANCER
A20: INTERMARCHE CANNES PONT DES GARBES | B20: =IFERROR(VLOOKUP($A20,VENTES!$C:E,3,FALSE),"") -> SCHLESSER | C20: =IFERROR(VLOOKUP($A20,VENTES!C:E,2,FALSE()),"") -> Direct | D20: =COUNTIF(VENTES!$C:$C,$A20) -> 1 | E20: =SUMIF(VENTES!$C:$C,$A20,VENTES!$F:$F) -> 320.16 | F20: =IFERROR(__xludf.DUMMYFUNCTION("IFERROR(MAX(FILTER(VENTES!$A:$A,VENTES!$C:$C=$A20)),"""")"),46065.0) -> 46065 | G20: =IF(F20="","",DATEDIF(F20,TODAY(),"M")) -> 7 | H20: =IFERROR(__xludf.DUMMYFUNCTION("IF(D20=0,0,D20 /MONTH(COUNTUNIQUE(FILTRE(VENTES!$A:$A,VENTES!$C:$C=$A20))) )"),0.08333333333333333) -> 0.083333333 | I20: =IF(G20="","",IF(G20 > PARAMETRES!B23,"À RELANCER","OK")) -> À RELANCER
A21: INTERMARCHE coulounieix chamiers (COCHAME) | B21: =IFERROR(VLOOKUP($A21,VENTES!$C:E,3,FALSE),"") -> CAP FRAIS | C21: =IFERROR(VLOOKUP($A21,VENTES!C:E,2,FALSE()),"") -> Direct | D21: =COUNTIF(VENTES!$C:$C,$A21) -> 1 | E21: =SUMIF(VENTES!$C:$C,$A21,VENTES!$F:$F) -> 426.88 | F21: =IFERROR(__xludf.DUMMYFUNCTION("IFERROR(MAX(FILTER(VENTES!$A:$A,VENTES!$C:$C=$A21)),"""")"),45964.0) -> 45964 | G21: =IF(F21="","",DATEDIF(F21,TODAY(),"M")) -> 10 | H21: =IFERROR(__xludf.DUMMYFUNCTION("IF(D21=0,0,D21 /MONTH(COUNTUNIQUE(FILTRE(VENTES!$A:$A,VENTES!$C:$C=$A21))) )"),0.08333333333333333) -> 0.083333333 | I21: =IF(G21="","",IF(G21 > PARAMETRES!B24,"À RELANCER","OK")) -> OK
A22: INTERMARCHE GRAND FOUGERAY (SAS ) | B22: =IFERROR(VLOOKUP($A22,VENTES!$C:E,3,FALSE),"") -> CAP FRAIS | C22: =IFERROR(VLOOKUP($A22,VENTES!C:E,2,FALSE()),"") -> Direct | D22: =COUNTIF(VENTES!$C:$C,$A22) -> 2 | E22: =SUMIF(VENTES!$C:$C,$A22,VENTES!$F:$F) -> 733.12 | F22: =IFERROR(__xludf.DUMMYFUNCTION("IFERROR(MAX(FILTER(VENTES!$A:$A,VENTES!$C:$C=$A22)),"""")"),46092.0) -> 46092 | G22: =IF(F22="","",DATEDIF(F22,TODAY(),"M")) -> 6 | H22: =IFERROR(__xludf.DUMMYFUNCTION("IF(D22=0,0,D22 /MONTH(COUNTUNIQUE(FILTRE(VENTES!$A:$A,VENTES!$C:$C=$A22))) )"),0.16666666666666666) -> 0.16666667 | I22: =IF(G22="","",IF(G22 > PARAMETRES!B25,"À RELANCER","OK")) -> OK
A23: LECLERC CERNAY | B23: =IFERROR(VLOOKUP($A23,VENTES!$C:E,3,FALSE),"") -> BROCARD | C23: =IFERROR(VLOOKUP($A23,VENTES!C:E,2,FALSE()),"") -> Direct | D23: =COUNTIF(VENTES!$C:$C,$A23) -> 4 | E23: =SUMIF(VENTES!$C:$C,$A23,VENTES!$F:$F) -> 1758.56 | F23: =IFERROR(__xludf.DUMMYFUNCTION("IFERROR(MAX(FILTER(VENTES!$A:$A,VENTES!$C:$C=$A23)),"""")"),46111.0) -> 46111 | G23: =IF(F23="","",DATEDIF(F23,TODAY(),"M")) -> 5 | H23: =IFERROR(__xludf.DUMMYFUNCTION("IF(D23=0,0,D23 /MONTH(COUNTUNIQUE(FILTRE(VENTES!$A:$A,VENTES!$C:$C=$A23))) )"),0.3333333333333333) -> 0.33333333 | I23: =IF(G23="","",IF(G23 > PARAMETRES!B26,"À RELANCER","OK")) -> À RELANCER
A24: LECLERC FLEURY LES AUBRAIS (SOCAMAINE) | B24: =IFERROR(VLOOKUP($A24,VENTES!$C:E,3,FALSE),"") -> CAP FRAIS | C24: =IFERROR(VLOOKUP($A24,VENTES!C:E,2,FALSE()),"") -> Direct | D24: =COUNTIF(VENTES!$C:$C,$A24) -> 1 | E24: =SUMIF(VENTES!$C:$C,$A24,VENTES!$F:$F) -> 457.12 | F24: =IFERROR(__xludf.DUMMYFUNCTION("IFERROR(MAX(FILTER(VENTES!$A:$A,VENTES!$C:$C=$A24)),"""")"),46034.0) -> 46034 | G24: =IF(F24="","",DATEDIF(F24,TODAY(),"M")) -> 8 | H24: =IFERROR(__xludf.DUMMYFUNCTION("IF(D24=0,0,D24 /MONTH(COUNTUNIQUE(FILTRE(VENTES!$A:$A,VENTES!$C:$C=$A24))) )"),0.08333333333333333) -> 0.083333333 | I24: =IF(G24="","",IF(G24 > PARAMETRES!B27,"À RELANCER","OK")) -> À RELANCER
A25: LECLERC OLONNE SUR MER (SODILONNE) | B25: =IFERROR(VLOOKUP($A25,VENTES!$C:E,3,FALSE),"") -> CAP FRAIS | C25: =IFERROR(VLOOKUP($A25,VENTES!C:E,2,FALSE()),"") -> Direct | D25: =COUNTIF(VENTES!$C:$C,$A25) -> 5 | E25: =SUMIF(VENTES!$C:$C,$A25,VENTES!$F:$F) -> 2681.92 | F25: =IFERROR(__xludf.DUMMYFUNCTION("IFERROR(MAX(FILTER(VENTES!$A:$A,VENTES!$C:$C=$A25)),"""")"),46224.0) -> 46224 | G25: =IF(F25="","",DATEDIF(F25,TODAY(),"M")) -> 2 | H25: =IFERROR(__xludf.DUMMYFUNCTION("IF(D25=0,0,D25 /MONTH(COUNTUNIQUE(FILTRE(VENTES!$A:$A,VENTES!$C:$C=$A25))) )"),0.4166666666666667) -> 0.41666667 | I25: =IF(G25="","",IF(G25 > PARAMETRES!B28,"À RELANCER","OK")) -> À RELANCER
A26: LECLERC SOCAMAINE SAS FONDIS | B26: =IFERROR(VLOOKUP($A26,VENTES!$C:E,3,FALSE),"") -> CAP FRAIS | C26: =IFERROR(VLOOKUP($A26,VENTES!C:E,2,FALSE()),"") -> Direct | D26: =COUNTIF(VENTES!$C:$C,$A26) -> 1 | E26: =SUMIF(VENTES!$C:$C,$A26,VENTES!$F:$F) -> 464 | F26: =IFERROR(__xludf.DUMMYFUNCTION("IFERROR(MAX(FILTER(VENTES!$A:$A,VENTES!$C:$C=$A26)),"""")"),45973.0) -> 45973 | G26: =IF(F26="","",DATEDIF(F26,TODAY(),"M")) -> 10 | H26: =IFERROR(__xludf.DUMMYFUNCTION("IF(D26=0,0,D26 /MONTH(COUNTUNIQUE(FILTRE(VENTES!$A:$A,VENTES!$C:$C=$A26))) )"),0.08333333333333333) -> 0.083333333 | I26: =IF(G26="","",IF(G26 > Mail!A2,"À RELANCER","OK")) -> OK
A27: LES PLATANES - ITM ROCHEFORT (SAS) | B27: =IFERROR(VLOOKUP($A27,VENTES!$C:E,3,FALSE),"") -> CAP FRAIS | C27: =IFERROR(VLOOKUP($A27,VENTES!C:E,2,FALSE()),"") -> Direct | D27: =COUNTIF(VENTES!$C:$C,$A27) -> 2 | E27: =SUMIF(VENTES!$C:$C,$A27,VENTES!$F:$F) -> 793.44 | F27: =IFERROR(__xludf.DUMMYFUNCTION("IFERROR(MAX(FILTER(VENTES!$A:$A,VENTES!$C:$C=$A27)),"""")"),46043.0) -> 46043 | G27: =IF(F27="","",DATEDIF(F27,TODAY(),"M")) -> 8 | H27: =IFERROR(__xludf.DUMMYFUNCTION("IF(D27=0,0,D27 /MONTH(COUNTUNIQUE(FILTRE(VENTES!$A:$A,VENTES!$C:$C=$A27))) )"),0.16666666666666666) -> 0.16666667 | I27: =IF(G27="","",IF(G27 > PARAMETRES!B30,"À RELANCER","OK")) -> À RELANCER
A28: OTERA SAS | B28: =IFERROR(VLOOKUP($A28,VENTES!$C:E,3,FALSE),"") -> CAP FRAIS | C28: =IFERROR(VLOOKUP($A28,VENTES!C:E,2,FALSE()),"") -> Centrale | D28: =COUNTIF(VENTES!$C:$C,$A28) -> 62 | E28: =SUMIF(VENTES!$C:$C,$A28,VENTES!$F:$F) -> 26423.75 | F28: =IFERROR(__xludf.DUMMYFUNCTION("IFERROR(MAX(FILTER(VENTES!$A:$A,VENTES!$C:$C=$A28)),"""")"),46260.0) -> 46260 | G28: =IF(F28="","",DATEDIF(F28,TODAY(),"M")) -> 0 | H28: =IFERROR(__xludf.DUMMYFUNCTION("IF(D28=0,0,D28 /MONTH(COUNTUNIQUE(FILTRE(VENTES!$A:$A,VENTES!$C:$C=$A28))) )"),5.166666666666667) -> 5.1666667 | I28: =IF(G28="","",IF(G28 > PARAMETRES!B31,"À RELANCER","OK")) -> OK
A29: RENOUEST ( E.LECLERC RENNES ) (SAS) | B29: =IFERROR(VLOOKUP($A29,VENTES!$C:E,3,FALSE),"") -> CAP FRAIS | C29: =IFERROR(VLOOKUP($A29,VENTES!C:E,2,FALSE()),"") -> Direct | D29: =COUNTIF(VENTES!$C:$C,$A29) -> 4 | E29: =SUMIF(VENTES!$C:$C,$A29,VENTES!$F:$F) -> 2490.44 | F29: =IFERROR(__xludf.DUMMYFUNCTION("IFERROR(MAX(FILTER(VENTES!$A:$A,VENTES!$C:$C=$A29)),"""")"),46188.0) -> 46188 | G29: =IF(F29="","",DATEDIF(F29,TODAY(),"M")) -> 3 | H29: =IFERROR(__xludf.DUMMYFUNCTION("IF(D29=0,0,D29 /MONTH(COUNTUNIQUE(FILTRE(VENTES!$A:$A,VENTES!$C:$C=$A29))) )"),0.3333333333333333) -> 0.33333333 | I29: =IF(G29="","",IF(G29 > PARAMETRES!B32,"À RELANCER","OK")) -> À RELANCER
A30: SA SUPER U L'EPINE (NOIRMOUTIER) | B30: =IFERROR(VLOOKUP($A30,VENTES!$C:E,3,FALSE),"") -> CAP FRAIS | C30: =IFERROR(VLOOKUP($A30,VENTES!C:E,2,FALSE()),"") -> Direct | D30: =COUNTIF(VENTES!$C:$C,$A30) -> 2 | E30: =SUMIF(VENTES!$C:$C,$A30,VENTES!$F:$F) -> 884.15 | F30: =IFERROR(__xludf.DUMMYFUNCTION("IFERROR(MAX(FILTER(VENTES!$A:$A,VENTES!$C:$C=$A30)),"""")"),46220.0) -> 46220 | G30: =IF(F30="","",DATEDIF(F30,TODAY(),"M")) -> 2 | H30: =IFERROR(__xludf.DUMMYFUNCTION("IF(D30=0,0,D30 /MONTH(COUNTUNIQUE(FILTRE(VENTES!$A:$A,VENTES!$C:$C=$A30))) )"),0.16666666666666666) -> 0.16666667 | I30: =IF(G30="","",IF(G30 > PARAMETRES!B33,"À RELANCER","OK")) -> À RELANCER
A31: SA TRUCHIDIM - SUPER U - TRUCHTERSHEIM | B31: =IFERROR(VLOOKUP($A31,VENTES!$C:E,3,FALSE),"") -> BROCARD | C31: =IFERROR(VLOOKUP($A31,VENTES!C:E,2,FALSE()),"") -> Direct | D31: =COUNTIF(VENTES!$C:$C,$A31) -> 2 | E31: =SUMIF(VENTES!$C:$C,$A31,VENTES!$F:$F) -> 974.4 | F31: =IFERROR(__xludf.DUMMYFUNCTION("IFERROR(MAX(FILTER(VENTES!$A:$A,VENTES!$C:$C=$A31)),"""")"),46119.0) -> 46119 | G31: =IF(F31="","",DATEDIF(F31,TODAY(),"M")) -> 5 | H31: =IFERROR(__xludf.DUMMYFUNCTION("IF(D31=0,0,D31 /MONTH(COUNTUNIQUE(FILTRE(VENTES!$A:$A,VENTES!$C:$C=$A31))) )"),0.16666666666666666) -> 0.16666667 | I31: =IF(G31="","",IF(G31 > PARAMETRES!B34,"À RELANCER","OK")) -> À RELANCER
A32: SAS AUCHAN SEMECOURT | B32: =IFERROR(VLOOKUP($A32,VENTES!$C:E,3,FALSE),"") -> BROCARD | C32: =IFERROR(VLOOKUP($A32,VENTES!C:E,2,FALSE()),"") -> Direct | D32: =COUNTIF(VENTES!$C:$C,$A32) -> 1 | E32: =SUMIF(VENTES!$C:$C,$A32,VENTES!$F:$F) -> 445.44 | F32: =IFERROR(__xludf.DUMMYFUNCTION("IFERROR(MAX(FILTER(VENTES!$A:$A,VENTES!$C:$C=$A32)),"""")"),46079.0) -> 46079 | G32: =IF(F32="","",DATEDIF(F32,TODAY(),"M")) -> 6 | H32: =IFERROR(__xludf.DUMMYFUNCTION("IF(D32=0,0,D32 /MONTH(COUNTUNIQUE(FILTRE(VENTES!$A:$A,VENTES!$C:$C=$A32))) )"),0.08333333333333333) -> 0.083333333 | I32: =IF(G32="","",IF(G32 > PARAMETRES!B35,"À RELANCER","OK")) -> À RELANCER
A33: SAS INTERMARCHE - PONT DES GARBES | B33: =IFERROR(VLOOKUP($A33,VENTES!$C:E,3,FALSE),"") -> SCHLESSER | C33: =IFERROR(VLOOKUP($A33,VENTES!C:E,2,FALSE()),"") -> Direct | D33: =COUNTIF(VENTES!$C:$C,$A33) -> 1 | E33: =SUMIF(VENTES!$C:$C,$A33,VENTES!$F:$F) -> 320.16 | F33: =IFERROR(__xludf.DUMMYFUNCTION("IFERROR(MAX(FILTER(VENTES!$A:$A,VENTES!$C:$C=$A33)),"""")"),46039.0) -> 46039 | G33: =IF(F33="","",DATEDIF(F33,TODAY(),"M")) -> 8 | H33: =IFERROR(__xludf.DUMMYFUNCTION("IF(D33=0,0,D33 /MONTH(COUNTUNIQUE(FILTRE(VENTES!$A:$A,VENTES!$C:$C=$A33))) )"),0.08333333333333333) -> 0.083333333 | I33: =IF(G33="","",IF(G33 > PARAMETRES!B36,"À RELANCER","OK")) -> À RELANCER
A34: SAS INTERMARCHE - ROURET | B34: =IFERROR(VLOOKUP($A34,VENTES!$C:E,3,FALSE),"") -> SCHLESSER | C34: =IFERROR(VLOOKUP($A34,VENTES!C:E,2,FALSE()),"") -> Direct | D34: =COUNTIF(VENTES!$C:$C,$A34) -> 1 | E34: =SUMIF(VENTES!$C:$C,$A34,VENTES!$F:$F) -> 320.16 | F34: =IFERROR(__xludf.DUMMYFUNCTION("IFERROR(MAX(FILTER(VENTES!$A:$A,VENTES!$C:$C=$A34)),"""")"),46039.0) -> 46039 | G34: =IF(F34="","",DATEDIF(F34,TODAY(),"M")) -> 8 | H34: =IFERROR(__xludf.DUMMYFUNCTION("IF(D34=0,0,D34 /MONTH(COUNTUNIQUE(FILTRE(VENTES!$A:$A,VENTES!$C:$C=$A34))) )"),0.08333333333333333) -> 0.083333333 | I34: =IF(G34="","",IF(G34 > PARAMETRES!B37,"À RELANCER","OK")) -> À RELANCER
A35: SAS INTERMARCHE LIMOGES | B35: =IFERROR(VLOOKUP($A35,VENTES!$C:E,3,FALSE),"") -> CAP FRAIS | C35: =IFERROR(VLOOKUP($A35,VENTES!C:E,2,FALSE()),"") -> Direct | D35: =COUNTIF(VENTES!$C:$C,$A35) -> 1 | E35: =SUMIF(VENTES!$C:$C,$A35,VENTES!$F:$F) -> 423.63 | F35: =IFERROR(__xludf.DUMMYFUNCTION("IFERROR(MAX(FILTER(VENTES!$A:$A,VENTES!$C:$C=$A35)),"""")"),46094.0) -> 46094 | G35: =IF(F35="","",DATEDIF(F35,TODAY(),"M")) -> 6 | H35: =IFERROR(__xludf.DUMMYFUNCTION("IF(D35=0,0,D35 /MONTH(COUNTUNIQUE(FILTRE(VENTES!$A:$A,VENTES!$C:$C=$A35))) )"),0.08333333333333333) -> 0.083333333 | I35: =IF(G35="","",IF(G35 > PARAMETRES!B38,"À RELANCER","OK")) -> À RELANCER
